Workbook

Sheet 문장
A1: No | B1: sNo | C1: 구분2_참고 | D1: 구분 | E1: 한국어 | F1: 힌트 | G1: 영어 | H1: 외운것 | I1: 틀린것 | J1: 날짜 | K1: 날짜1차 | L1: 날짜2차 | M1: 날짜3차 | N1: 외운것2차 | O1: 외운것3차 | P1: 틀린것_1차 | Q1: 틀린것_2차 | R1: 틀린것_3차
A2: 1 | B2: 1 | C2: 기본문 훈련 | D2: 기본문 훈련 | E2: 나는 책을 읽는다 | F2: 나 - 읽는다 - 책 | G2: I read a book. | H2: {=MIN(SUMIF('외운 것'!A2:A271,A2,'외운 것'!D2:D271)+IF(R2=0,3,IF(R2=1,2,0)),3)} -> 3 | I2: {=_xlfn.COUNTIFS('외운 것'!A2:A271,A2,'외운 것'!D2:D271,0)} -> 0 | J2: {=IF(R2<>0,IF(H2>=3,_xlfn.XLOOKUP(A2,'외운 것'!A2:A271,'외운 것'!C2:C271,0,1),0),"3차")} -> 3차 | K2: {=IF(P2<>0,IF(N2>=3,_xlfn.XLOOKUP(A2,'외운 것'!A2:A271,'외운 것'!C2:C271,0,1),0),"1차")} -> 1차 | L2: {=IF(Q2<>0,IF(N2>=3,_xlfn.XLOOKUP(A2,'외운 것'!A2:A271,'외운 것'!C2:C271,0,1),0),"2차")} -> 2차 | M2: {=IF(R2<>0,IF(O2>=3,_xlfn.XLOOKUP(B2,'외운 것'!B2:B271,'외운 것'!D2:D271,0,1),0),"3차")} -> 3차 | N2: 3 | O2: 3 | P2: 0 | Q2: 0 | R2: 0
A3: 2 | B3: 2 | C3: 기본문 훈련 | D3: 기본문 훈련 | E3: 그는 음식을 요리한다 | F3: 그 - 요리한다 - 음식 | G3: He cooks food. | H3: {=MIN(SUMIF('외운 것'!A2:A271,A3,'외운 것'!D2:D271)+IF(R3=0,3,IF(R3=1,2,0)),3)} -> 3 | I3: {=_xlfn.COUNTIFS('외운 것'!A2:A271,A3,'외운 것'!D2:D271,0)} -> 0 | J3: {=IF(R3<>0,IF(H3>=3,_xlfn.XLOOKUP(A3,'외운 것'!A2:A271,'외운 것'!C2:C271,0,1),0),"3차")} -> 3차 | K3: {=IF(P3<>0,IF(N3>=3,_xlfn.XLOOKUP(A3,'외운 것'!A2:A271,'외운 것'!C2:C271,0,1),0),"1차")} -> 1차 | L3: {=IF(Q3<>0,IF(N3>=3,_xlfn.XLOOKUP(A3,'외운 것'!A2:A271,'외운 것'!C2:C271,0,1),0),"2차")} -> 2차 | M3: {=IF(R3<>0,IF(O3>=3,_xlfn.XLOOKUP(B3,'외운 것'!B2:B271,'외운 것'!D2:D271,0,1),0),"3차")} -> 3차 | N3: 3 | O3: 3 | P3: 0 | Q3: 0 | R3: 0
A4: 3 | B4: 3 | C4: 기본문 훈련 | D4: 기본문 훈련 | E4: 그녀는 편지를 쓴다 | F4: 그녀 - 쓴다 - 편지 | G4: She writes a letter. | H4: {=MIN(SUMIF('외운 것'!A2:A271,A4,'외운 것'!D2:D271)+IF(R4=0,3,IF(R4=1,2,0)),3)} -> 3 | I4: {=_xlfn.COUNTIFS('외운 것'!A2:A271,A4,'외운 것'!D2:D271,0)} -> 0 | J4: {=IF(R4<>0,IF(H4>=3,_xlfn.XLOOKUP(A4,'외운 것'!A2:A271,'외운 것'!C2:C271,0,1),0),"3차")} -> 3차 | K4: {=IF(P4<>0,IF(N4>=3,_xlfn.XLOOKUP(A4,'외운 것'!A2:A271,'외운 것'!C2:C271,0,1),0),"1차")} -> 1차 | L4: {=IF(Q4<>0,IF(N4>=3,_xlfn.XLOOKUP(A4,'외운 것'!A2:A271,'외운 것'!C2:C271,0,1),0),"2차")} -> 2차 | M4: {=IF(R4<>0,IF(O4>=3,_xlfn.XLOOKUP(B4,'외운 것'!B2:B271,'외운 것'!D2:D271,0,1),0),"3차")} -> 3차 | N4: 3 | O4: 3 | P4: 0 | Q4: 0 | R4: 0
A5: 4 | B5: 4 | C5: 기본문 훈련 | D5: 기본문 훈련 | E5: 우리는 영화를 본다 | F5: 우리 - 본다 - 영화 | G5: We watch a movie. | H5: {=MIN(SUMIF('외운 것'!A2:A271,A5,'외운 것'!D2:D271)+IF(R5=0,3,IF(R5=1,2,0)),3)} -> 3 | I5: {=_xlfn.COUNTIFS('외운 것'!A2:A271,A5,'외운 것'!D2:D271,0)} -> 0 | J5: {=IF(R5<>0,IF(H5>=3,_xlfn.XLOOKUP(A5,'외운 것'!A2:A271,'외운 것'!C2:C271,0,1),0),"3차")} -> 3차 | K5: {=IF(P5<>0,IF(N5>=3,_xlfn.XLOOKUP(A5,'외운 것'!A2:A271,'외운 것'!C2:C271,0,1),0),"1차")} -> 1차 | L5: {=IF(Q5<>0,IF(N5>=3,_xlfn.XLOOKUP(A5,'외운 것'!A2:A271,'외운 것'!C2:C271,0,1),0),"2차")} -> 2차 | M5: {=IF(R5<>0,IF(O5>=3,_xlfn.XLOOKUP(B5,'외운 것'!B2:B271,'외운 것'!D2:D271,0,1),0),"3차")} -> 3차 | N5: 3 | O5: 3 | P5: 0 | Q5: 0 | R5: 0
A6: 5 | B6: 5 | C6: 기본문 훈련 | D6: 기본문 훈련 | E6: 너는 음악을 듣는다 | F6: 너 - 듣는다 - 음악 | G6: You listen to music. | H6: {=MIN(SUMIF('외운 것'!A2:A271,A6,'외운 것'!D2:D271)+IF(R6=0,3,IF(R6=1,2,0)),3)} -> 3 | I6: {=_xlfn.COUNTIFS('외운 것'!A2:A271,A6,'외운 것'!D2:D271,0)} -> 0 | J6: {=IF(R6<>0,IF(H6>=3,_xlfn.XLOOKUP(A6,'외운 것'!A2:A271,'외운 것'!C2:C271,0,1),0),"3차")} -> 3차 | K6: {=IF(P6<>0,IF(N6>=3,_xlfn.XLOOKUP(A6,'외운 것'!A2:A271,'외운 것'!C2:C271,0,1),0),"1차")} -> 0 | L6: {=IF(Q6<>0,IF(N6>=3,_xlfn.XLOOKUP(A6,'외운 것'!A2:A271,'외운 것'!C2:C271,0,1),0),"2차")} -> 2차 | M6: {=IF(R6<>0,IF(O6>=3,_xlfn.XLOOKUP(B6,'외운 것'!B2:B271,'외운 것'!D2:D271,0,1),0),"3차")} -> 3차 | N6: 2 | O6: 3 | P6: 1 | Q6: 0 | R6: 0
A7: 6 | B7: 6 | C7: 기본문 훈련 | D7: 기본문 훈련 | E7: 그들은 게임을 한다 | F7: 그들 - 한다 - 게임 | G7: They play a game. | H7: {=MIN(SUMIF('외운 것'!A2:A271,A7,'외운 것'!D2:D271)+IF(R7=0,3,IF(R7=1,2,0)),3)} -> 3 | I7: {=_xlfn.COUNTIFS('외운 것'!A2:A271,A7,'외운 것'!D2:D271,0)} -> 0 | J7: {=IF(R7<>0,IF(H7>=3,_xlfn.XLOOKUP(A7,'외운 것'!A2:A271,'외운 것'!C2:C271,0,1),0),"3차")} -> 3차 | K7: {=IF(P7<>0,IF(N7>=3,_xlfn.XLOOKUP(A7,'외운 것'!A2:A271,'외운 것'!C2:C271,0,1),0),"1차")} -> 1차 | L7: {=IF(Q7<>0,IF(N7>=3,_xlfn.XLOOKUP(A7,'외운 것'!A2:A271,'외운 것'!C2:C271,0,1),0),"2차")} -> 2차 | M7: {=IF(R7<>0,IF(O7>=3,_xlfn.XLOOKUP(B7,'외운 것'!B2:B271,'외운 것'!D2:D271,0,1),0),"3차")} -> 3차 | N7: 3 | O7: 3 | P7: 0 | Q7: 0 | R7: 0
A8: 7 | B8: 7 | C8: 기본문 훈련 | D8: 기본문 훈련 | E8: 나는 커피를 마신다 | F8: 나 - 마신다 - 커피 | G8: I drink coffee. | H8: {=MIN(SUMIF('외운 것'!A2:A271,A8,'외운 것'!D2:D271)+IF(R8=0,3,IF(R8=1,2,0)),3)} -> 3 | I8: {=_xlfn.COUNTIFS('외운 것'!A2:A271,A8,'외운 것'!D2:D271,0)} -> 0 | J8: {=IF(R8<>0,IF(H8>=3,_xlfn.XLOOKUP(A8,'외운 것'!A2:A271,'외운 것'!C2:C271,0,1),0),"3차")} -> 3차 | K8: {=IF(P8<>0,IF(N8>=3,_xlfn.XLOOKUP(A8,'외운 것'!A2:A271,'외운 것'!C2:C271,0,1),0),"1차")} -> 1차 | L8: {=IF(Q8<>0,IF(N8>=3,_xlfn.XLOOKUP(A8,'외운 것'!A2:A271,'외운 것'!C2:C271,0,1),0),"2차")} -> 2차 | M8: {=IF(R8<>0,IF(O8>=3,_xlfn.XLOOKUP(B8,'외운 것'!B2:B271,'외운 것'!D2:D271,0,1),0),"3차")} -> 3차 | N8: 3 | O8: 3 | P8: 0 | Q8: 0 | R8: 0
A9: 8 | B9: 8 | C9: 기본문 훈련 | D9: 기본문 훈련 | E9: 그는 차를 운전한다 | F9: 그 - 운전한다 - 차 | G9: He drives a car. | H9: {=MIN(SUMIF('외운 것'!A2:A271,A9,'외운 것'!D2:D271)+IF(R9=0,3,IF(R9=1,2,0)),3)} -> 3 | I9: {=_xlfn.COUNTIFS('외운 것'!A2:A271,A9,'외운 것'!D2:D271,0)} -> 0 | J9: {=IF(R9<>0,IF(H9>=3,_xlfn.XLOOKUP(A9,'외운 것'!A2:A271,'외운 것'!C2:C271,0,1),0),"3차")} -> 3차 | K9: {=IF(P9<>0,IF(N9>=3,_xlfn.XLOOKUP(A9,'외운 것'!A2:A271,'외운 것'!C2:C271,0,1),0),"1차")} -> 1차 | L9: {=IF(Q9<>0,IF(N9>=3,_xlfn.XLOOKUP(A9,'외운 것'!A2:A271,'외운 것'!C2:C271,0,1),0),"2차")} -> 2차 | M9: {=IF(R9<>0,IF(O9>=3,_xlfn.XLOOKUP(B9,'외운 것'!B2:B271,'외운 것'!D2:D271,0,1),0),"3차")} -> 3차 | N9: 3 | O9: 3 | P9: 0 | Q9: 0 | R9: 0
A10: 9 | B10: 9 | C10: 기본문 훈련 | D10: 기본문 훈련 | E10: 그녀는 방을 청소한다 | F10: 그녀 - 청소한다 - 방 | G10: She cleans the room. | H10: {=MIN(SUMIF('외운 것'!A2:A271,A10,'외운 것'!D2:D271)+IF(R10=0,3,IF(R10=1,2,0)),3)} -> 3 | I10: {=_xlfn.COUNTIFS('외운 것'!A2:A271,A10,'외운 것'!D2:D271,0)} -> 0 | J10: {=IF(R10<>0,IF(H10>=3,_xlfn.XLOOKUP(A10,'외운 것'!A2:A271,'외운 것'!C2:C271,0,1),0),"3차")} -> 3차 | K10: {=IF(P10<>0,IF(N10>=3,_xlfn.XLOOKUP(A10,'외운 것'!A2:A271,'외운 것'!C2:C271,0,1),0),"1차")} -> 1차 | L10: {=IF(Q10<>0,IF(N10>=3,_xlfn.XLOOKUP(A10,'외운 것'!A2:A271,'외운 것'!C2:C271,0,1),0),"2차")} -> 2차 | M10: {=IF(R10<>0,IF(O10>=3,_xlfn.XLOOKUP(B10,'외운 것'!B2:B271,'외운 것'!D2:D271,0,1),0),"3차")} -> 3차 | N10: 3 | O10: 3 | P10: 0 | Q10: 0 | R10: 0
A11: 10 | B11: 10 | C11: 기본문 훈련 | D11: 기본문 훈련 | E11: 우리는 문제를 푼다 | F11: 우리 - 푼다 - 문제 | G11: We solve a problem. | H11: {=MIN(SUMIF('외운 것'!A2:A271,A11,'외운 것'!D2:D271)+IF(R11=0,3,IF(R11=1,2,0)),3)} -> 3 | I11: {=_xlfn.COUNTIFS('외운 것'!A2:A271,A11,'외운 것'!D2:D271,0)} -> 0 | J11: {=IF(R11<>0,IF(H11>=3,_xlfn.XLOOKUP(A11,'외운 것'!A2:A271,'외운 것'!C2:C271,0,1),0),"3차")} -> 3차 | K11: {=IF(P11<>0,IF(N11>=3,_xlfn.XLOOKUP(A11,'외운 것'!A2:A271,'외운 것'!C2:C271,0,1),0),"1차")} -> 1차 | L11: {=IF(Q11<>0,IF(N11>=3,_xlfn.XLOOKUP(A11,'외운 것'!A2:A271,'외운 것'!C2:C271,0,1),0),"2차")} -> 2차 | M11: {=IF(R11<>0,IF(O11>=3,_xlfn.XLOOKUP(B11,'외운 것'!B2:B271,'외운 것'!D2:D271,0,1),0),"3차")} -> 3차 | N11: 3 | O11: 3 | P11: 0 | Q11: 0 | R11: 0
A12: 11 | B12: 11 | C12: 기본문 훈련 | D12: 기본문 훈련 | E12: 우리는 저녁을 먹는다. | F12: 우리 - 먹는다 - 저녁 | G12: We eat dinner. | H12: {=MIN(SUMIF('외운 것'!A2:A271,A12,'외운 것'!D2:D271)+IF(R12=0,3,IF(R12=1,2,0)),3)} -> 3 | I12: {=_xlfn.COUNTIFS('외운 것'!A2:A271,A12,'외운 것'!D2:D271,0)} -> 0 | J12: {=IF(R12<>0,IF(H12>=3,_xlfn.XLOOKUP(A12,'외운 것'!A2:A271,'외운 것'!C2:C271,0,1),0),"3차")} -> 3차 | K12: {=IF(P12<>0,IF(N12>=3,_xlfn.XLOOKUP(A12,'외운 것'!A2:A271,'외운 것'!C2:C271,0,1),0),"1차")} -> 0 | L12: {=IF(Q12<>0,IF(N12>=3,_xlfn.XLOOKUP(A12,'외운 것'!A2:A271,'외운 것'!C2:C271,0,1),0),"2차")} -> 0 | M12: {=IF(R12<>0,IF(O12>=3,_xlfn.XLOOKUP(B12,'외운 것'!B2:B271,'외운 것'!D2:D271,0,1),0),"3차")} -> 3차 | N12: 2 | O12: 3 | P12: 1 | Q12: 1 | R12: 0
A13: 12 | B13: 12 | C13: 기본문 훈련 | D13: 기본문 훈련 | E13: 그는 축구를 한다. | F13: 그 - 한다 - 축구 | G13: He plays soccer. | H13: {=MIN(SUMIF('외운 것'!A2:A271,A13,'외운 것'!D2:D271)+IF(R13=0,3,IF(R13=1,2,0)),3)} -> 3 | I13: {=_xlfn.COUNTIFS('외운 것'!A2:A271,A13,'외운 것'!D2:D271,0)} -> 0 | J13: {=IF(R13<>0,IF(H13>=3,_xlfn.XLOOKUP(A13,'외운 것'!A2:A271,'외운 것'!C2:C271,0,1),0),"3차")} -> 3차 | K13: {=IF(P13<>0,IF(N13>=3,_xlfn.XLOOKUP(A13,'외운 것'!A2:A271,'외운 것'!C2:C271,0,1),0),"1차")} -> 1차 | L13: {=IF(Q13<>0,IF(N13>=3,_xlfn.XLOOKUP(A13,'외운 것'!A2:A271,'외운 것'!C2:C271,0,1),0),"2차")} -> 2차 | M13: {=IF(R13<>0,IF(O13>=3,_xlfn.XLOOKUP(B13,'외운 것'!B2:B271,'외운 것'!D2:D271,0,1),0),"3차")} -> 3차 | N13: 3 | O13: 3 | P13: 0 | Q13: 0 | R13: 0
A14: 13 | B14: 13 | C14: 기본문 훈련 | D14: 기본문 훈련 | E14: 아이는 사탕을 좋아한다. | F14: 아이 - 좋아한다 - 사탕 | G14: The child likes candy. | H14: {=MIN(SUMIF('외운 것'!A2:A271,A14,'외운 것'!D2:D271)+IF(R14=0,3,IF(R14=1,2,0)),3)} -> 3 | I14: {=_xlfn.COUNTIFS('외운 것'!A2:A271,A14,'외운 것'!D2:D271,0)} -> 0 | J14: {=IF(R14<>0,IF(H14>=3,_xlfn.XLOOKUP(A14,'외운 것'!A2:A271,'외운 것'!C2:C271,0,1),0),"3차")} -> 3차 | K14: {=IF(P14<>0,IF(N14>=3,_xlfn.XLOOKUP(A14,'외운 것'!A2:A271,'외운 것'!C2:C271,0,1),0),"1차")} -> 1차 | L14: {=IF(Q14<>0,IF(N14>=3,_xlfn.XLOOKUP(A14,'외운 것'!A2:A271,'외운 것'!C2:C271,0,1),0),"2차")} -> 2차 | M14: {=IF(R14<>0,IF(O14>=3,_xlfn.XLOOKUP(B14,'외운 것'!B2:B271,'외운 것'!D2:D271,0,1),0),"3차")} -> 3차 | N14: 3 | O14: 3 | P14: 0 | Q14: 0 | R14: 0
A15: 14 | B15: 14 | C15: 기본문 훈련 | D15: 기본문 훈련 | E15: 그녀는 영어를 공부한다. | F15: 그녀 - 공부한다 - 영어 | G15: She studies English. | H15: {=MIN(SUMIF('외운 것'!A2:A271,A15,'외운 것'!D2:D271)+IF(R15=0,3,IF(R15=1,2,0)),3)} -> 3 | I15: {=_xlfn.COUNTIFS('외운 것'!A2:A271,A15,'외운 것'!D2:D271,0)} -> 0 | J15: {=IF(R15<>0,IF(H15>=3,_xlfn.XLOOKUP(A15,'외운 것'!A2:A271,'외운 것'!C2:C271,0,1),0),"3차")} -> 3차 | K15: {=IF(P15<>0,IF(N15>=3,_xlfn.XLOOKUP(A15,'외운 것'!A2:A271,'외운 것'!C2:C271,0,1),0),"1차")} -> 1차 | L15: {=IF(Q15<>0,IF(N15>=3,_xlfn.XLOOKUP(A15,'외운 것'!A2:A271,'외운 것'!C2:C271,0,1),0),"2차")} -> 2차 | M15: {=IF(R15<>0,IF(O15>=3,_xlfn.XLOOKUP(B15,'외운 것'!B2:B271,'외운 것'!D2:D271,0,1),0),"3차")} -> 3차 | N15: 3 | O15: 3 | P15: 0 | Q15: 0 | R15: 0
A16: 15 | B16: 15 | C16: 기본문 훈련 | D16: 기본문 훈련 | E16: 그는 물을 마신다. | F16: 그 - 마신다 - 물 | G16: He drinks water. | H16: {=MIN(SUMIF('외운 것'!A2:A271,A16,'외운 것'!D2:D271)+IF(R16=0,3,IF(R16=1,2,0)),3)} -> 3 | I16: {=_xlfn.COUNTIFS('외운 것'!A2:A271,A16,'외운 것'!D2:D271,0)} -> 0 | J16: {=IF(R16<>0,IF(H16>=3,_xlfn.XLOOKUP(A16,'외운 것'!A2:A271,'외운 것'!C2:C271,0,1),0),"3차")} -> 3차 | K16: {=IF(P16<>0,IF(N16>=3,_xlfn.XLOOKUP(A16,'외운 것'!A2:A271,'외운 것'!C2:C271,0,1),0),"1차")} -> 1차 | L16: {=IF(Q16<>0,IF(N16>=3,_xlfn.XLOOKUP(A16,'외운 것'!A2:A271,'외운 것'!C2:C271,0,1),0),"2차")} -> 2차 | M16: {=IF(R16<>0,IF(O16>=3,_xlfn.XLOOKUP(B16,'외운 것'!B2:B271,'외운 것'!D2:D271,0,1),0),"3차")} -> 3차 | N16: 3 | O16: 3 | P16: 0 | Q16: 0 | R16: 0
A17: 16 | B17: 16 | C17: 기본문 훈련 | D17: 기본문 훈련 | E17: 나는 슬프다 | F17: 나 - 이다 - 슬픈 상태 | G17: I am sad. | H17: {=MIN(SUMIF('외운 것'!A2:A271,A17,'외운 것'!D2:D271)+IF(R17=0,3,IF(R17=1,2,0)),3)} -> 3 | I17: {=_xlfn.COUNTIFS('외운 것'!A2:A271,A17,'외운 것'!D2:D271,0)} -> 0 | J17: {=IF(R17<>0,IF(H17>=3,_xlfn.XLOOKUP(A17,'외운 것'!A2:A271,'외운 것'!C2:C271,0,1),0),"3차")} -> 3차 | K17: {=IF(P17<>0,IF(N17>=3,_xlfn.XLOOKUP(A17,'외운 것'!A2:A271,'외운 것'!C2:C271,0,1),0),"1차")} -> 1차 | L17: {=IF(Q17<>0,IF(N17>=3,_xlfn.XLOOKUP(A17,'외운 것'!A2:A271,'외운 것'!C2:C271,0,1),0),"2차")} -> 2차 | M17: {=IF(R17<>0,IF(O17>=3,_xlfn.XLOOKUP(B17,'외운 것'!B2:B271,'외운 것'!D2:D271,0,1),0),"3차")} -> 3차 | N17: 3 | O17: 3 | P17: 0 | Q17: 0 | R17: 0
A18: 17 | B18: 17 | C18: 기본문 훈련 | D18: 기본문 훈련 | E18: 그는 피곤하다 | F18: 그 - 이다 - 피곤한 상태 | G18: He is tired. | H18: {=MIN(SUMIF('외운 것'!A2:A271,A18,'외운 것'!D2:D271)+IF(R18=0,3,IF(R18=1,2,0)),3)} -> 3 | I18: {=_xlfn.COUNTIFS('외운 것'!A2:A271,A18,'외운 것'!D2:D271,0)} -> 0 | J18: {=IF(R18<>0,IF(H18>=3,_xlfn.XLOOKUP(A18,'외운 것'!A2:A271,'외운 것'!C2:C271,0,1),0),"3차")} -> 3차 | K18: {=IF(P18<>0,IF(N18>=3,_xlfn.XLOOKUP(A18,'외운 것'!A2:A271,'외운 것'!C2:C271,0,1),0),"1차")} -> 1차 | L18: {=IF(Q18<>0,IF(N18>=3,_xlfn.XLOOKUP(A18,'외운 것'!A2:A271,'외운 것'!C2:C271,0,1),0),"2차")} -> 2차 | M18: {=IF(R18<>0,IF(O18>=3,_xlfn.XLOOKUP(B18,'외운 것'!B2:B271,'외운 것'!D2:D271,0,1),0),"3차")} -> 3차 | N18: 3 | O18: 3 | P18: 0 | Q18: 0 | R18: 0
A19: 18 | B19: 18 | C19: 기본문 훈련 | D19: 기본문 훈련 | E19: 그녀는 행복하다. | F19: 그녀 - 이다 - 행복한 상태 | G19: She is happy. | H19: {=MIN(SUMIF('외운 것'!A2:A271,A19,'외운 것'!D2:D271)+IF(R19=0,3,IF(R19=1,2,0)),3)} -> 3 | I19: {=_xlfn.COUNTIFS('외운 것'!A2:A271,A19,'외운 것'!D2:D271,0)} -> 0 | J19: {=IF(R19<>0,IF(H19>=3,_xlfn.XLOOKUP(A19,'외운 것'!A2:A271,'외운 것'!C2:C271,0,1),0),"3차")} -> 3차 | K19: {=IF(P19<>0,IF(N19>=3,_xlfn.XLOOKUP(A19,'외운 것'!A2:A271,'외운 것'!C2:C271,0,1),0),"1차")} -> 1차 | L19: {=IF(Q19<>0,IF(N19>=3,_xlfn.XLOOKUP(A19,'외운 것'!A2:A271,'외운 것'!C2:C271,0,1),0),"2차")} -> 2차 | M19: {=IF(R19<>0,IF(O19>=3,_xlfn.XLOOKUP(B19,'외운 것'!B2:B271,'외운 것'!D2:D271,0,1),0),"3차")} -> 3차 | N19: 3 | O19: 3 | P19: 0 | Q19: 0 | R19: 0
A20: 19 | B20: 19 | C20: 기본문 훈련 | D20: 기본문 훈련 | E20: 우리는 배고프다 | F20: 우리 - 이다 - 배고픈 상태 | G20: We are hungry. | H20: {=MIN(SUMIF('외운 것'!A2:A271,A20,'외운 것'!D2:D271)+IF(R20=0,3,IF(R20=1,2,0)),3)} -> 3 | I20: {=_xlfn.COUNTIFS('외운 것'!A2:A271,A20,'외운 것'!D2:D271,0)} -> 0 | J20: {=IF(R20<>0,IF(H20>=3,_xlfn.XLOOKUP(A20,'외운 것'!A2:A271,'외운 것'!C2:C271,0,1),0),"3차")} -> 3차 | K20: {=IF(P20<>0,IF(N20>=3,_xlfn.XLOOKUP(A20,'외운 것'!A2:A271,'외운 것'!C2:C271,0,1),0),"1차")} -> 1차 | L20: {=IF(Q20<>0,IF(N20>=3,_xlfn.XLOOKUP(A20,'외운 것'!A2:A271,'외운 것'!C2:C271,0,1),0),"2차")} -> 2차 | M20: {=IF(R20<>0,IF(O20>=3,_xlfn.XLOOKUP(B20,'외운 것'!B2:B271,'외운 것'!D2:D271,0,1),0),"3차")} -> 3차 | N20: 3 | O20: 3 | P20: 0 | Q20: 0 | R20: 0
A21: 20 | B21: 20 | C21: 기본문 훈련 | D21: 기본문 훈련 | E21: 너는 신나다 | F21: 너 - 이다 - 신난 상태 | G21: You are excited. | H21: {=MIN(SUMIF('외운 것'!A2:A271,A21,'외운 것'!D2:D271)+IF(R21=0,3,IF(R21=1,2,0)),3)} -> 3 | I21: {=_xlfn.COUNTIFS('외운 것'!A2:A271,A21,'외운 것'!D2:D271,0)} -> 0 | J21: {=IF(R21<>0,IF(H21>=3,_xlfn.XLOOKUP(A21,'외운 것'!A2:A271,'외운 것'!C2:C271,0,1),0),"3차")} -> 3차 | K21: {=IF(P21<>0,IF(N21>=3,_xlfn.XLOOKUP(A21,'외운 것'!A2:A271,'외운 것'!C2:C271,0,1),0),"1차")} -> 0 | L21: {=IF(Q21<>0,IF(N21>=3,_xlfn.XLOOKUP(A21,'외운 것'!A2:A271,'외운 것'!C2:C271,0,1),0),"2차")} -> 2차 | M21: {=IF(R21<>0,IF(O21>=3,_xlfn.XLOOKUP(B21,'외운 것'!B2:B271,'외운 것'!D2:D271,0,1),0),"3차")} -> 3차 | N21: 2 | O21: 3 | P21: 1 | Q21: 0 | R21: 0
A22: 21 | B22: 21 | C22: 기본문 훈련 | D22: 기본문 훈련 | E22: 그들은 화가 났다 | F22: 그들 - 이다 - 화난 상태 | G22: They are angry. | H22: {=MIN(SUMIF('외운 것'!A2:A271,A22,'외운 것'!D2:D271)+IF(R22=0,3,IF(R22=1,2,0)),3)} -> 3 | I22: {=_xlfn.COUNTIFS('외운 것'!A2:A271,A22,'외운 것'!D2:D271,0)} -> 0 | J22: {=IF(R22<>0,IF(H22>=3,_xlfn.XLOOKUP(A22,'외운 것'!A2:A271,'외운 것'!C2:C271,0,1),0),"3차")} -> 3차 | K22: {=IF(P22<>0,IF(N22>=3,_xlfn.XLOOKUP(A22,'외운 것'!A2:A271,'외운 것'!C2:C271,0,1),0),"1차")} -> 1차 | L22: {=IF(Q22<>0,IF(N22>=3,_xlfn.XLOOKUP(A22,'외운 것'!A2:A271,'외운 것'!C2:C271,0,1),0),"2차")} -> 2차 | M22: {=IF(R22<>0,IF(O22>=3,_xlfn.XLOOKUP(B22,'외운 것'!B2:B271,'외운 것'!D2:D271,0,1),0),"3차")} -> 3차 | N22: 3 | O22: 3 | P22: 0 | Q22: 0 | R22: 0
A23: 22 | B23: 22 | C23: 기본문 훈련 | D23: 기본문 훈련 | E23: 나는 지루하다 | F23: 나 - 이다 - 지루한 상태 | G23: I am bored. | H23: {=MIN(SUMIF('외운 것'!A2:A271,A23,'외운 것'!D2:D271)+IF(R23=0,3,IF(R23=1,2,0)),3)} -> 3 | I23: {=_xlfn.COUNTIFS('외운 것'!A2:A271,A23,'외운 것'!D2:D271,0)} -> 0 | J23: {=IF(R23<>0,IF(H23>=3,_xlfn.XLOOKUP(A23,'외운 것'!A2:A271,'외운 것'!C2:C271,0,1),0),"3차")} -> 3차 | K23: {=IF(P23<>0,IF(N23>=3,_xlfn.XLOOKUP(A23,'외운 것'!A2:A271,'외운 것'!C2:C271,0,1),0),"1차")} -> 1차 | L23: {=IF(Q23<>0,IF(N23>=3,_xlfn.XLOOKUP(A23,'외운 것'!A2:A271,'외운 것'!C2:C271,0,1),0),"2차")} -> 2차 | M23: {=IF(R23<>0,IF(O23>=3,_xlfn.XLOOKUP(B23,'외운 것'!B2:B271,'외운 것'!D2:D271,0,1),0),"3차")} -> 3차 | N23: 3 | O23: 3 | P23: 0 | Q23: 0 | R23: 0
A24: 23 | B24: 23 | C24: 기본문 훈련 | D24: 기본문 훈련 | E24: 그는 걱정된다 | F24: 그 - 이다 - 걱정된 상태 | G24: He is worried. | H24: {=MIN(SUMIF('외운 것'!A2:A271,A24,'외운 것'!D2:D271)+IF(R24=0,3,IF(R24=1,2,0)),3)} -> 3 | I24: {=_xlfn.COUNTIFS('외운 것'!A2:A271,A24,'외운 것'!D2:D271,0)} -> 0 | J24: {=IF(R24<>0,IF(H24>=3,_xlfn.XLOOKUP(A24,'외운 것'!A2:A271,'외운 것'!C2:C271,0,1),0),"3차")} -> 3차 | K24: {=IF(P24<>0,IF(N24>=3,_xlfn.XLOOKUP(A24,'외운 것'!A2:A271,'외운 것'!C2:C271,0,1),0),"1차")} -> 1차 | L24: {=IF(Q24<>0,IF(N24>=3,_xlfn.XLOOKUP(A24,'외운 것'!A2:A271,'외운 것'!C2:C271,0,1),0),"2차")} -> 2차 | M24: {=IF(R24<>0,IF(O24>=3,_xlfn.XLOOKUP(B24,'외운 것'!B2:B271,'외운 것'!D2:D271,0,1),0),"3차")} -> 3차 | N24: 3 | O24: 3 | P24: 0 | Q24: 0 | R24: 0
A25: 24 | B25: 24 | C25: 기본문 훈련 | D25: 기본문 훈련 | E25: 그녀는 놀랐다 | F25: 그녀 - 이다 - 놀란 상태 | G25: She is surprised. | H25: {=MIN(SUMIF('외운 것'!A2:A271,A25,'외운 것'!D2:D271)+IF(R25=0,3,IF(R25=1,2,0)),3)} -> 3 | I25: {=_xlfn.COUNTIFS('외운 것'!A2:A271,A25,'외운 것'!D2:D271,0)} -> 0 | J25: {=IF(R25<>0,IF(H25>=3,_xlfn.XLOOKUP(A25,'외운 것'!A2:A271,'외운 것'!C2:C271,0,1),0),"3차")} -> 3차 | K25: {=IF(P25<>0,IF(N25>=3,_xlfn.XLOOKUP(A25,'외운 것'!A2:A271,'외운 것'!C2:C271,0,1),0),"1차")} -> 1차 | L25: {=IF(Q25<>0,IF(N25>=3,_xlfn.XLOOKUP(A25,'외운 것'!A2:A271,'외운 것'!C2:C271,0,1),0),"2차")} -> 2차 | M25: {=IF(R25<>0,IF(O25>=3,_xlfn.XLOOKUP(B25,'외운 것'!B2:B271,'외운 것'!D2:D271,0,1),0),"3차")} -> 3차 | N25: 3 | O25: 3 | P25: 0 | Q25: 0 | R25: 0
A26: 25 | B26: 25 | C26: 기본문 훈련 | D26: 기본문 훈련 | E26: 우리는 만족스럽다 | F26: 우리 - 이다 - 만족스러운 상태 | G26: We are satisfied. | H26: {=MIN(SUMIF('외운 것'!A2:A271,A26,'외운 것'!D2:D271)+IF(R26=0,3,IF(R26=1,2,0)),3)} -> 3 | I26: {=_xlfn.COUNTIFS('외운 것'!A2:A271,A26,'외운 것'!D2:D271,0)} -> 0 | J26: {=IF(R26<>0,IF(H26>=3,_xlfn.XLOOKUP(A26,'외운 것'!A2:A271,'외운 것'!C2:C271,0,1),0),"3차")} -> 3차 | K26: {=IF(P26<>0,IF(N26>=3,_xlfn.XLOOKUP(A26,'외운 것'!A2:A271,'외운 것'!C2:C271,0,1),0),"1차")} -> 0 | L26: {=IF(Q26<>0,IF(N26>=3,_xlfn.XLOOKUP(A26,'외운 것'!A2:A271,'외운 것'!C2:C271,0,1),0),"2차")} -> 2차 | M26: {=IF(R26<>0,IF(O26>=3,_xlfn.XLOOKUP(B26,'외운 것'!B2:B271,'외운 것'!D2:D271,0,1),0),"3차")} -> 3차 | N26: 0 | O26: 3 | P26: 2 | Q26: 0 | R26: 0
A27: 26 | B27: 26 | C27: 기본문 훈련 | D27: 기본문 훈련 | E27: 나는 행복하다. | F27: 나 - 이다 - 행복한 상태 | G27: I am happy. | H27: {=MIN(SUMIF('외운 것'!A2:A271,A27,'외운 것'!D2:D271)+IF(R27=0,3,IF(R27=1,2,0)),3)} -> 3 | I27: {=_xlfn.COUNTIFS('외운 것'!A2:A271,A27,'외운 것'!D2:D271,0)} -> 0 | J27: {=IF(R27<>0,IF(H27>=3,_xlfn.XLOOKUP(A27,'외운 것'!A2:A271,'외운 것'!C2:C271,0,1),0),"3차")} -> 3차 | K27: {=IF(P27<>0,IF(N27>=3,_xlfn.XLOOKUP(A27,'외운 것'!A2:A271,'외운 것'!C2:C271,0,1),0),"1차")} -> 1차 | L27: {=IF(Q27<>0,IF(N27>=3,_xlfn.XLOOKUP(A27,'외운 것'!A2:A271,'외운 것'!C2:C271,0,1),0),"2차")} -> 2차 | M27: {=IF(R27<>0,IF(O27>=3,_xlfn.XLOOKUP(B27,'외운 것'!B2:B271,'외운 것'!D2:D271,0,1),0),"3차")} -> 3차 | N27: 3 | O27: 3 | P27: 0 | Q27: 0 | R27: 0
A28: 27 | B28: 27 | C28: 기본문 훈련 | D28: 기본문 훈련 | E28: 그녀는 피곤하다. | F28: 그녀 - 이다 - 피곤한 상태 | G28: She is tired. | H28: {=MIN(SUMIF('외운 것'!A2:A271,A28,'외운 것'!D2:D271)+IF(R28=0,3,IF(R28=1,2,0)),3)} -> 3 | I28: {=_xlfn.COUNTIFS('외운 것'!A2:A271,A28,'외운 것'!D2:D271,0)} -> 0 | J28: {=IF(R28<>0,IF(H28>=3,_xlfn.XLOOKUP(A28,'외운 것'!A2:A271,'외운 것'!C2:C271,0,1),0),"3차")} -> 3차 | K28: {=IF(P28<>0,IF(N28>=3,_xlfn.XLOOKUP(A28,'외운 것'!A2:A271,'외운 것'!C2:C271,0,1),0),"1차")} -> 1차 | L28: {=IF(Q28<>0,IF(N28>=3,_xlfn.XLOOKUP(A28,'외운 것'!A2:A271,'외운 것'!C2:C271,0,1),0),"2차")} -> 2차 | M28: {=IF(R28<>0,IF(O28>=3,_xlfn.XLOOKUP(B28,'외운 것'!B2:B271,'외운 것'!D2:D271,0,1),0),"3차")} -> 3차 | N28: 3 | O28: 3 | P28: 0 | Q28: 0 | R28: 0
A29: 28 | B29: 28 | C29: 기본문 훈련 | D29: 기본문 훈련 | E29: 그들은 슬프다. | F29: 그들 - 이다 - 슬픈 상태 | G29: They are sad. | H29: {=MIN(SUMIF('외운 것'!A2:A271,A29,'외운 것'!D2:D271)+IF(R29=0,3,IF(R29=1,2,0)),3)} -> 3 | I29: {=_xlfn.COUNTIFS('외운 것'!A2:A271,A29,'외운 것'!D2:D271,0)} -> 0 | J29: {=IF(R29<>0,IF(H29>=3,_xlfn.XLOOKUP(A29,'외운 것'!A2:A271,'외운 것'!C2:C271,0,1),0),"3차")} -> 3차 | K29: {=IF(P29<>0,IF(N29>=3,_xlfn.XLOOKUP(A29,'외운 것'!A2:A271,'외운 것'!C2:C271,0,1),0),"1차")} -> 1차 | L29: {=IF(Q29<>0,IF(N29>=3,_xlfn.XLOOKUP(A29,'외운 것'!A2:A271,'외운 것'!C2:C271,0,1),0),"2차")} -> 2차 | M29: {=IF(R29<>0,IF(O29>=3,_xlfn.XLOOKUP(B29,'외운 것'!B2:B271,'외운 것'!D2:D271,0,1),0),"3차")} -> 3차 | N29: 3 | O29: 3 | P29: 0 | Q29: 0 | R29: 0
A30: 29 | B30: 29 | C30: 기본문 훈련 | D30: 기본문 훈련 | E30: 우리는 기쁘다. | F30: 우리 - 이다 - 기쁜 상태 | G30: We are glad. | H30: {=MIN(SUMIF('외운 것'!A2:A271,A30,'외운 것'!D2:D271)+IF(R30=0,3,IF(R30=1,2,0)),3)} -> 3 | I30: {=_xlfn.COUNTIFS('외운 것'!A2:A271,A30,'외운 것'!D2:D271,0)} -> 0 | J30: {=IF(R30<>0,IF(H30>=3,_xlfn.XLOOKUP(A30,'외운 것'!A2:A271,'외운 것'!C2:C271,0,1),0),"3차")} -> 3차 | K30: {=IF(P30<>0,IF(N30>=3,_xlfn.XLOOKUP(A30,'외운 것'!A2:A271,'외운 것'!C2:C271,0,1),0),"1차")} -> 0 | L30: {=IF(Q30<>0,IF(N30>=3,_xlfn.XLOOKUP(A30,'외운 것'!A2:A271,'외운 것'!C2:C271,0,1),0),"2차")} -> 2차 | M30: {=IF(R30<>0,IF(O30>=3,_xlfn.XLOOKUP(B30,'외운 것'!B2:B271,'외운 것'!D2:D271,0,1),0),"3차")} -> 3차 | N30: 2 | O30: 3 | P30: 1 | Q30: 0 | R30: 0
A31: 30 | B31: 30 | C31: 기본문 훈련 | D31: 기본문 훈련 | E31: 그는 화나다. | F31: 그 - 이다 - 화난 상태 | G31: He is angry. | H31: {=MIN(SUMIF('외운 것'!A2:A271,A31,'외운 것'!D2:D271)+IF(R31=0,3,IF(R31=1,2,0)),3)} -> 3 | I31: {=_xlfn.COUNTIFS('외운 것'!A2:A271,A31,'외운 것'!D2:D271,0)} -> 0 | J31: {=IF(R31<>0,IF(H31>=3,_xlfn.XLOOKUP(A31,'외운 것'!A2:A271,'외운 것'!C2:C271,0,1),0),"3차")} -> 3차 | K31: {=IF(P31<>0,IF(N31>=3,_xlfn.XLOOKUP(A31,'외운 것'!A2:A271,'외운 것'!C2:C271,0,1),0),"1차")} -> 1차 | L31: {=IF(Q31<>0,IF(N31>=3,_xlfn.XLOOKUP(A31,'외운 것'!A2:A271,'외운 것'!C2:C271,0,1),0),"2차")} -> 2차 | M31: {=IF(R31<>0,IF(O31>=3,_xlfn.XLOOKUP(B31,'외운 것'!B2:B271,'외운 것'!D2:D271,0,1),0),"3차")} -> 3차 | N31: 3 | O31: 3 | P31: 0 | Q31: 0 | R31: 0
A32: 31 | B32: 31 | C32: 기본문 훈련 | D32: 기본문 훈련 | E32: 나는 준비되었다. | F32: 나 - 이다 - 준비된 상태 | G32: I am ready. | H32: {=MIN(SUMIF('외운 것'!A2:A271,A32,'외운 것'!D2:D271)+IF(R32=0,3,IF(R32=1,2,0)),3)} -> 3 | I32: {=_xlfn.COUNTIFS('외운 것'!A2:A271,A32,'외운 것'!D2:D271,0)} -> 0 | J32: {=IF(R32<>0,IF(H32>=3,_xlfn.XLOOKUP(A32,'외운 것'!A2:A271,'외운 것'!C2:C271,0,1),0),"3차")} -> 3차 | K32: {=IF(P32<>0,IF(N32>=3,_xlfn.XLOOKUP(A32,'외운 것'!A2:A271,'외운 것'!C2:C271,0,1),0),"1차")} -> 1차 | L32: {=IF(Q32<>0,IF(N32>=3,_xlfn.XLOOKUP(A32,'외운 것'!A2:A271,'외운 것'!C2:C271,0,1),0),"2차")} -> 2차 | M32: {=IF(R32<>0,IF(O32>=3,_xlfn.XLOOKUP(B32,'외운 것'!B2:B271,'외운 것'!D2:D271,0,1),0),"3차")} -> 3차 | N32: 3 | O32: 3 | P32: 0 | Q32: 0 | R32: 0
A33: 32 | B33: 32 | C33: 기본문 훈련 | D33: 기본문 훈련 | E33: 그녀는 똑똑하다. | F33: 그녀 - 이다 - 똑똑한 상태 | G33: She is smart. | H33: {=MIN(SUMIF('외운 것'!A2:A271,A33,'외운 것'!D2:D271)+IF(R33=0,3,IF(R33=1,2,0)),3)} -> 3 | I33: {=_xlfn.COUNTIFS('외운 것'!A2:A271,A33,'외운 것'!D2:D271,0)} -> 0 | J33: {=IF(R33<>0,IF(H33>=3,_xlfn.XLOOKUP(A33,'외운 것'!A2:A271,'외운 것'!C2:C271,0,1),0),"3차")} -> 3차 | K33: {=IF(P33<>0,IF(N33>=3,_xlfn.XLOOKUP(A33,'외운 것'!A2:A271,'외운 것'!C2:C271,0,1),0),"1차")} -> 1차 | L33: {=IF(Q33<>0,IF(N33>=3,_xlfn.XLOOKUP(A33,'외운 것'!A2:A271,'외운 것'!C2:C271,0,1),0),"2차")} -> 2차 | M33: {=IF(R33<>0,IF(O33>=3,_xlfn.XLOOKUP(B33,'외운 것'!B2:B271,'외운 것'!D2:D271,0,1),0),"3차")} -> 3차 | N33: 3 | O33: 3 | P33: 0 | Q33: 0 | R33: 0
A34: 33 | B34: 33 | C34: 기본문 훈련 | D34: 기본문 훈련 | E34: 우리는 지루하다. | F34: 우리 - 이다 - 지루한 상태 | G34: We are bored. | H34: {=MIN(SUMIF('외운 것'!A2:A271,A34,'외운 것'!D2:D271)+IF(R34=0,3,IF(R34=1,2,0)),3)} -> 3 | I34: {=_xlfn.COUNTIFS('외운 것'!A2:A271,A34,'외운 것'!D2:D271,0)} -> 0 | J34: {=IF(R34<>0,IF(H34>=3,_xlfn.XLOOKUP(A34,'외운 것'!A2:A271,'외운 것'!C2:C271,0,1),0),"3차")} -> 3차 | K34: {=IF(P34<>0,IF(N34>=3,_xlfn.XLOOKUP(A34,'외운 것'!A2:A271,'외운 것'!C2:C271,0,1),0),"1차")} -> 1차 | L34: {=IF(Q34<>0,IF(N34>=3,_xlfn.XLOOKUP(A34,'외운 것'!A2:A271,'외운 것'!C2:C271,0,1),0),"2차")} -> 2차 | M34: {=IF(R34<>0,IF(O34>=3,_xlfn.XLOOKUP(B34,'외운 것'!B2:B271,'외운 것'!D2:D271,0,1),0),"3차")} -> 3차 | N34: 3 | O34: 3 | P34: 0 | Q34: 0 | R34: 0
A35: 34 | B35: 34 | C35: 기본문 훈련 | D35: 기본문 훈련 | E35: 그는 건강하다. | F35: 그 - 이다 - 건강한 상태 | G35: He is healthy. | H35: {=MIN(SUMIF('외운 것'!A2:A271,A35,'외운 것'!D2:D271)+IF(R35=0,3,IF(R35=1,2,0)),3)} -> 3 | I35: {=_xlfn.COUNTIFS('외운 것'!A2:A271,A35,'외운 것'!D2:D271,0)} -> 0 | J35: {=IF(R35<>0,IF(H35>=3,_xlfn.XLOOKUP(A35,'외운 것'!A2:A271,'외운 것'!C2:C271,0,1),0),"3차")} -> 3차 | K35: {=IF(P35<>0,IF(N35>=3,_xlfn.XLOOKUP(A35,'외운 것'!A2:A271,'외운 것'!C2:C271,0,1),0),"1차")} -> 1차 | L35: {=IF(Q35<>0,IF(N35>=3,_xlfn.XLOOKUP(A35,'외운 것'!A2:A271,'외운 것'!C2:C271,0,1),0),"2차")} -> 2차 | M35: {=IF(R35<>0,IF(O35>=3,_xlfn.XLOOKUP(B35,'외운 것'!B2:B271,'외운 것'!D2:D271,0,1),0),"3차")} -> 3차 | N35: 3 | O35: 3 | P35: 0 | Q35: 0 | R35: 0
A36: 35 | B36: 35 | C36: 기본문 훈련 | D36: 기본문 훈련 | E36: 나는 바쁘다. | F36: 나 - 이다 - 바쁜 상태 | G36: I am busy. | H36: {=MIN(SUMIF('외운 것'!A2:A271,A36,'외운 것'!D2:D271)+IF(R36=0,3,IF(R36=1,2,0)),3)} -> 3 | I36: {=_xlfn.COUNTIFS('외운 것'!A2:A271,A36,'외운 것'!D2:D271,0)} -> 0 | J36: {=IF(R36<>0,IF(H36>=3,_xlfn.XLOOKUP(A36,'외운 것'!A2:A271,'외운 것'!C2:C271,0,1),0),"3차")} -> 3차 | K36: {=IF(P36<>0,IF(N36>=3,_xlfn.XLOOKUP(A36,'외운 것'!A2:A271,'외운 것'!C2:C271,0,1),0),"1차")} -> 1차 | L36: {=IF(Q36<>0,IF(N36>=3,_xlfn.XLOOKUP(A36,'외운 것'!A2:A271,'외운 것'!C2:C271,0,1),0),"2차")} -> 2차 | M36: {=IF(R36<>0,IF(O36>=3,_xlfn.XLOOKUP(B36,'외운 것'!B2:B271,'외운 것'!D2:D271,0,1),0),"3차")} -> 3차 | N36: 3 | O36: 3 | P36: 0 | Q36: 0 | R36: 0
A37: 36 | B37: 1 | C37: 동사1+동사2 | D37: 동사1+동사2 | E37: 우리는 그 책을 읽기를 계획하고 있다. | F37: 우리 - 계획하고 있다 - to 읽다 - 그 책 | G37: We plan to read the book. | H37: {=MIN(SUMIF('외운 것'!A2:A271,A37,'외운 것'!D2:D271)+IF(R37=0,3,IF(R37=1,2,0)),3)} -> 3 | I37: {=_xlfn.COUNTIFS('외운 것'!A2:A271,A37,'외운 것'!D2:D271,0)} -> 0 | J37: {=IF(R37<>0,IF(H37>=3,_xlfn.XLOOKUP(A37,'외운 것'!A2:A271,'외운 것'!C2:C271,0,1),0),"3차")} -> 3차 | K37: {=IF(P37<>0,IF(N37>=3,_xlfn.XLOOKUP(A37,'외운 것'!A2:A271,'외운 것'!C2:C271,0,1),0),"1차")} -> 1차 | L37: {=IF(Q37<>0,IF(N37>=3,_xlfn.XLOOKUP(A37,'외운 것'!A2:A271,'외운 것'!C2:C271,0,1),0),"2차")} -> 2차 | M37: {=IF(R37<>0,IF(O37>=3,_xlfn.XLOOKUP(B37,'외운 것'!B2:B271,'외운 것'!D2:D271,0,1),0),"3차")} -> 3차 | N37: 3 | O37: 3 | P37: 0 | Q37: 0 | R37: 0
A38: 37 | B38: 2 | C38: 동사1+동사2 | D38: 동사1+동사2 | E38: 나는 설거지하는 것을 싫어한다. | F38: 나 - 싫어한다 - 설거지하다 ing | G38: I hate washing dishes. | H38: {=MIN(SUMIF('외운 것'!A2:A271,A38,'외운 것'!D2:D271)+IF(R38=0,3,IF(R38=1,2,0)),3)} -> 3 | I38: {=_xlfn.COUNTIFS('외운 것'!A2:A271,A38,'외운 것'!D2:D271,0)} -> 0 | J38: {=IF(R38<>0,IF(H38>=3,_xlfn.XLOOKUP(A38,'외운 것'!A2:A271,'외운 것'!C2:C271,0,1),0),"3차")} -> 3차 | K38: {=IF(P38<>0,IF(N38>=3,_xlfn.XLOOKUP(A38,'외운 것'!A2:A271,'외운 것'!C2:C271,0,1),0),"1차")} -> 0 | L38: {=IF(Q38<>0,IF(N38>=3,_xlfn.XLOOKUP(A38,'외운 것'!A2:A271,'외운 것'!C2:C271,0,1),0),"2차")} -> 2차 | M38: {=IF(R38<>0,IF(O38>=3,_xlfn.XLOOKUP(B38,'외운 것'!B2:B271,'외운 것'!D2:D271,0,1),0),"3차")} -> 3차 | N38: 2 | O38: 3 | P38: 1 | Q38: 0 | R38: 0
A39: 38 | B39: 3 | C39: 동사1+동사2 | D39: 동사1+동사2 | E39: 그는 새로운 언어를 배우기를 희망한다. | F39: 그 - 희망한다 - to 배우다 - 새로운 언어 | G39: He hopes to learn a new language. | H39: {=MIN(SUMIF('외운 것'!A2:A271,A39,'외운 것'!D2:D271)+IF(R39=0,3,IF(R39=1,2,0)),3)} -> 3 | I39: {=_xlfn.COUNTIFS('외운 것'!A2:A271,A39,'외운 것'!D2:D271,0)} -> 0 | J39: {=IF(R39<>0,IF(H39>=3,_xlfn.XLOOKUP(A39,'외운 것'!A2:A271,'외운 것'!C2:C271,0,1),0),"3차")} -> 3차 | K39: {=IF(P39<>0,IF(N39>=3,_xlfn.XLOOKUP(A39,'외운 것'!A2:A271,'외운 것'!C2:C271,0,1),0),"1차")} -> 0 | L39: {=IF(Q39<>0,IF(N39>=3,_xlfn.XLOOKUP(A39,'외운 것'!A2:A271,'외운 것'!C2:C271,0,1),0),"2차")} -> 0 | M39: {=IF(R39<>0,IF(O39>=3,_xlfn.XLOOKUP(B39,'외운 것'!B2:B271,'외운 것'!D2:D271,0,1),0),"3차")} -> 3차 | N39: 0 | O39: 3 | P39: 2 | Q39: 1 | R39: 0
A40: 39 | B40: 4 | C40: 동사1+동사2 | D40: 동사1+동사2 | E40: 우리는 수영하는 것을 그만뒀다. | F40: 우리 - 그만뒀다 - 수영하다 ing | G40: We quit swimming. | H40: {=MIN(SUMIF('외운 것'!A2:A271,A40,'외운 것'!D2:D271)+IF(R40=0,3,IF(R40=1,2,0)),3)} -> 3 | I40: {=_xlfn.COUNTIFS('외운 것'!A2:A271,A40,'외운 것'!D2:D271,0)} -> 0 | J40: {=IF(R40<>0,IF(H40>=3,_xlfn.XLOOKUP(A40,'외운 것'!A2:A271,'외운 것'!C2:C271,0,1),0),"3차")} -> 3차 | K40: {=IF(P40<>0,IF(N40>=3,_xlfn.XLOOKUP(A40,'외운 것'!A2:A271,'외운 것'!C2:C271,0,1),0),"1차")} -> 0 | L40: {=IF(Q40<>0,IF(N40>=3,_xlfn.XLOOKUP(A40,'외운 것'!A2:A271,'외운 것'!C2:C271,0,1),0),"2차")} -> 0 | M40: {=IF(R40<>0,IF(O40>=3,_xlfn.XLOOKUP(B40,'외운 것'!B2:B271,'외운 것'!D2:D271,0,1),0),"3차")} -> 3차 | N40: 0 | O40: 3 | P40: 2 | Q40: 1 | R40: 0
...

Sheet 외운 것
A1: No2 | B1: 영어2 | C1: 날짜2 | D1: 외운것2 | E1: 맞춘 수 | F1: 순서
A2: 464 | B2: Has she cooked this dish? | C2: 2026-04-30 | D2: 0 | E2: {=_xlfn.COUNTIFS(D2:D271,1,A2:A271,A2)} -> 0 | F2: {=(YEAR(C2)-2025)*1000+MONTH(C2)*31+DAY(C2)+A2} -> 1618
A3: 462 | B3: Has he heard that song? | C3: 2026-04-30 | D3: 1 | E3: {=_xlfn.COUNTIFS(D2:D271,1,A2:A271,A3)} -> 1 | F3: {=(YEAR(C3)-2025)*1000+MONTH(C3)*31+DAY(C3)+A3} -> 1616
A4: 460 | B4: Has she been to France? | C4: 2026-04-30 | D4: 1 | E4: {=_xlfn.COUNTIFS(D2:D271,1,A2:A271,A4)} -> 1 | F4: {=(YEAR(C4)-2025)*1000+MONTH(C4)*31+DAY(C4)+A4} -> 1614
A5: 457 | B5: Have you used it? | C5: 2026-04-30 | D5: 0 | E5: {=_xlfn.COUNTIFS(D2:D271,1,A2:A271,A5)} -> 0 | F5: {=(YEAR(C5)-2025)*1000+MONTH(C5)*31+DAY(C5)+A5} -> 1611
A6: 455 | B6: Does he exercise on the weekend? | C6: 2026-04-30 | D6: 0 | E6: {=_xlfn.COUNTIFS(D2:D271,1,A2:A271,A6)} -> 0 | F6: {=(YEAR(C6)-2025)*1000+MONTH(C6)*31+DAY(C6)+A6} -> 1609
A7: 431 | B7: He achieved such an amazing result that it surprised everyone. | C7: 2026-04-30 | D7: 0 | E7: {=_xlfn.COUNTIFS(D2:D271,1,A2:A271,A7)} -> 0 | F7: {=(YEAR(C7)-2025)*1000+MONTH(C7)*31+DAY(C7)+A7} -> 1585
A8: 424 | B8: It appears that he is crazy. | C8: 2026-04-30 | D8: 0 | E8: {=_xlfn.COUNTIFS(D2:D271,1,A2:A271,A8)} -> 0 | F8: {=(YEAR(C8)-2025)*1000+MONTH(C8)*31+DAY(C8)+A8} -> 1578
A9: 422 | B9: I am worried about that he will come to the party. | C9: 2026-04-30 | D9: 1 | E9: {=_xlfn.COUNTIFS(D2:D271,1,A2:A271,A9)} -> 1 | F9: {=(YEAR(C9)-2025)*1000+MONTH(C9)*31+DAY(C9)+A9} -> 1576
A10: 418 | B10: That he deceived me made me angry. | C10: 2026-04-30 | D10: 0 | E10: {=_xlfn.COUNTIFS(D2:D271,1,A2:A271,A10)} -> 0 | F10: {=(YEAR(C10)-2025)*1000+MONTH(C10)*31+DAY(C10)+A10} -> 1572
A11: 414 | B11: I think that he asked for help. | C11: 2026-04-30 | D11: 0 | E11: {=_xlfn.COUNTIFS(D2:D271,1,A2:A271,A11)} -> 1 | F11: {=(YEAR(C11)-2025)*1000+MONTH(C11)*31+DAY(C11)+A11} -> 1568
A12: 414 | B12: I think that he asked for help. | C12: 2026-04-30 | D12: 1 | E12: {=_xlfn.COUNTIFS(D2:D271,1,A2:A271,A12)} -> 1 | F12: {=(YEAR(C12)-2025)*1000+MONTH(C12)*31+DAY(C12)+A12} -> 1568
A13: 407 | B13: That he will help us is clear. | C13: 2026-04-30 | D13: 1 | E13: {=_xlfn.COUNTIFS(D2:D271,1,A2:A271,A13)} -> 1 | F13: {=(YEAR(C13)-2025)*1000+MONTH(C13)*31+DAY(C13)+A13} -> 1561
A14: 401 | B14: She wrote a note lest she forget things. | C14: 2026-04-30 | D14: 0 | E14: {=_xlfn.COUNTIFS(D2:D271,1,A2:A271,A14)} -> 1 | F14: {=(YEAR(C14)-2025)*1000+MONTH(C14)*31+DAY(C14)+A14} -> 1555
A15: 401 | B15: She wrote a note lest she forget things. | C15: 2026-04-30 | D15: 1 | E15: {=_xlfn.COUNTIFS(D2:D271,1,A2:A271,A15)} -> 1 | F15: {=(YEAR(C15)-2025)*1000+MONTH(C15)*31+DAY(C15)+A15} -> 1555
A16: 398 | B16: We can catch the train if you hurry. | C16: 2026-04-30 | D16: 1 | E16: {=_xlfn.COUNTIFS(D2:D271,1,A2:A271,A16)} -> 2 | F16: {=(YEAR(C16)-2025)*1000+MONTH(C16)*31+DAY(C16)+A16} -> 1552
A17: 398 | B17: We can catch the train if you hurry. | C17: 2026-04-30 | D17: 1 | E17: {=_xlfn.COUNTIFS(D2:D271,1,A2:A271,A17)} -> 2 | F17: {=(YEAR(C17)-2025)*1000+MONTH(C17)*31+DAY(C17)+A17} -> 1552
A18: 394 | B18: He worked until it was night. | C18: 2026-04-30 | D18: 0 | E18: {=_xlfn.COUNTIFS(D2:D271,1,A2:A271,A18)} -> 1 | F18: {=(YEAR(C18)-2025)*1000+MONTH(C18)*31+DAY(C18)+A18} -> 1548
A19: 394 | B19: He worked until it was night. | C19: 2026-04-30 | D19: 1 | E19: {=_xlfn.COUNTIFS(D2:D271,1,A2:A271,A19)} -> 1 | F19: {=(YEAR(C19)-2025)*1000+MONTH(C19)*31+DAY(C19)+A19} -> 1548
A20: 389 | B20: It rained when I left. | C20: 2026-04-30 | D20: 0 | E20: {=_xlfn.COUNTIFS(D2:D271,1,A2:A271,A20)} -> 1 | F20: {=(YEAR(C20)-2025)*1000+MONTH(C20)*31+DAY(C20)+A20} -> 1543
A21: 389 | B21: It rained when I left. | C21: 2026-04-30 | D21: 1 | E21: {=_xlfn.COUNTIFS(D2:D271,1,A2:A271,A21)} -> 1 | F21: {=(YEAR(C21)-2025)*1000+MONTH(C21)*31+DAY(C21)+A21} -> 1543
A22: 386 | B22: He had dinner and took a walk. | C22: 2026-04-30 | D22: 0 | E22: {=_xlfn.COUNTIFS(D2:D271,1,A2:A271,A22)} -> 0 | F22: {=(YEAR(C22)-2025)*1000+MONTH(C22)*31+DAY(C22)+A22} -> 1540
A23: 386 | B23: He had dinner and took a walk. | C23: 2026-04-30 | D23: 0 | E23: {=_xlfn.COUNTIFS(D2:D271,1,A2:A271,A23)} -> 0 | F23: {=(YEAR(C23)-2025)*1000+MONTH(C23)*31+DAY(C23)+A23} -> 1540
A24: 385 | B24: She took a map lest she get lost. | C24: 2026-04-30 | D24: 0 | E24: {=_xlfn.COUNTIFS(D2:D271,1,A2:A271,A24)} -> 1 | F24: {=(YEAR(C24)-2025)*1000+MONTH(C24)*31+DAY(C24)+A24} -> 1539
A25: 385 | B25: She took a map lest she get lost. | C25: 2026-04-30 | D25: 1 | E25: {=_xlfn.COUNTIFS(D2:D271,1,A2:A271,A25)} -> 1 | F25: {=(YEAR(C25)-2025)*1000+MONTH(C25)*31+DAY(C25)+A25} -> 1539
A26: 376 | B26: We had coffee after we watched a movie. | C26: 2026-04-30 | D26: 0 | E26: {=_xlfn.COUNTIFS(D2:D271,1,A2:A271,A26)} -> 0 | F26: {=(YEAR(C26)-2025)*1000+MONTH(C26)*31+DAY(C26)+A26} -> 1530
A27: 376 | B27: We had coffee after we watched a movie. | C27: 2026-04-30 | D27: 0 | E27: {=_xlfn.COUNTIFS(D2:D271,1,A2:A271,A27)} -> 0 | F27: {=(YEAR(C27)-2025)*1000+MONTH(C27)*31+DAY(C27)+A27} -> 1530
A28: 373 | B28: The class ended when I arrived. | C28: 2026-04-30 | D28: 1 | E28: {=_xlfn.COUNTIFS(D2:D271,1,A2:A271,A28)} -> 2 | F28: {=(YEAR(C28)-2025)*1000+MONTH(C28)*31+DAY(C28)+A28} -> 1527
A29: 373 | B29: The class ended when I arrived. | C29: 2026-04-30 | D29: 1 | E29: {=_xlfn.COUNTIFS(D2:D271,1,A2:A271,A29)} -> 2 | F29: {=(YEAR(C29)-2025)*1000+MONTH(C29)*31+DAY(C29)+A29} -> 1527
A30: 370 | B30: He read a book and went to sleep. | C30: 2026-04-30 | D30: 1 | E30: {=_xlfn.COUNTIFS(D2:D271,1,A2:A271,A30)} -> 2 | F30: {=(YEAR(C30)-2025)*1000+MONTH(C30)*31+DAY(C30)+A30} -> 1524
A31: 370 | B31: He read a book and went to sleep. | C31: 2026-04-30 | D31: 1 | E31: {=_xlfn.COUNTIFS(D2:D271,1,A2:A271,A31)} -> 2 | F31: {=(YEAR(C31)-2025)*1000+MONTH(C31)*31+DAY(C31)+A31} -> 1524
A32: 369 | B32: She worked carefully lest she make a mistake. | C32: 2026-04-30 | D32: 0 | E32: {=_xlfn.COUNTIFS(D2:D271,1,A2:A271,A32)} -> 1 | F32: {=(YEAR(C32)-2025)*1000+MONTH(C32)*31+DAY(C32)+A32} -> 1523
A33: 369 | B33: She worked carefully lest she make a mistake. | C33: 2026-04-30 | D33: 1 | E33: {=_xlfn.COUNTIFS(D2:D271,1,A2:A271,A33)} -> 1 | F33: {=(YEAR(C33)-2025)*1000+MONTH(C33)*31+DAY(C33)+A33} -> 1523
A34: 364 | B34: I was tired because I didn't get enough sleep. | C34: 2026-04-30 | D34: 0 | E34: {=_xlfn.COUNTIFS(D2:D271,1,A2:A271,A34)} -> 1 | F34: {=(YEAR(C34)-2025)*1000+MONTH(C34)*31+DAY(C34)+A34} -> 1518
A35: 364 | B35: I was tired because I didn't get enough sleep. | C35: 2026-04-30 | D35: 1 | E35: {=_xlfn.COUNTIFS(D2:D271,1,A2:A271,A35)} -> 1 | F35: {=(YEAR(C35)-2025)*1000+MONTH(C35)*31+DAY(C35)+A35} -> 1518
A36: 363 | B36: We have been friends since we were children. | C36: 2026-04-30 | D36: 0 | E36: {=_xlfn.COUNTIFS(D2:D271,1,A2:A271,A36)} -> 2 | F36: {=(YEAR(C36)-2025)*1000+MONTH(C36)*31+DAY(C36)+A36} -> 1517
A37: 363 | B37: We have been friends since we were children. | C37: 2026-04-30 | D37: 1 | E37: {=_xlfn.COUNTIFS(D2:D271,1,A2:A271,A37)} -> 2 | F37: {=(YEAR(C37)-2025)*1000+MONTH(C37)*31+DAY(C37)+A37} -> 1517
A38: 363 | B38: We have been friends since we were children. | C38: 2026-04-30 | D38: 1 | E38: {=_xlfn.COUNTIFS(D2:D271,1,A2:A271,A38)} -> 2 | F38: {=(YEAR(C38)-2025)*1000+MONTH(C38)*31+DAY(C38)+A38} -> 1517
A39: 362 | B39: They continued the party until the last guest left. | C39: 2026-04-30 | D39: 0 | E39: {=_xlfn.COUNTIFS(D2:D271,1,A2:A271,A39)} -> 1 | F39: {=(YEAR(C39)-2025)*1000+MONTH(C39)*31+DAY(C39)+A39} -> 1516
A40: 362 | B40: They continued the party until the last guest left. | C40: 2026-04-30 | D40: 1 | E40: {=_xlfn.COUNTIFS(D2:D271,1,A2:A271,A40)} -> 1 | F40: {=(YEAR(C40)-2025)*1000+MONTH(C40)*31+DAY(C40)+A40} -> 1516
...

Sheet 총괄 - 맞춘 문장(3번)
A1: 맞춘 문장(3번)
B2: 날짜 | C2: 맞춘갯수(순서체크) | D2: 회차
A3: 날짜: | C3: 합계:
A4: 46082 | C4: =SUM(C5:C28) -> 0
B5: 46089 | C5: {=COUNTIF('문장'!J2:J724,B5)} -> 0 | D5: {=COUNTIF('외운 것'!C2:C271,B5)/30} -> 0
B6: 46090 | C6: {=COUNTIF('문장'!J2:J724,B6)} -> 0 | D6: {=COUNTIF('외운 것'!C2:C271,B6)/30} -> 0
B7: 46091 | C7: {=COUNTIF('문장'!J2:J724,B7)} -> 0 | D7: {=COUNTIF('외운 것'!C2:C271,B7)/30} -> 0
B8: 46092 | C8: {=COUNTIF('문장'!J2:J724,B8)} -> 0 | D8: {=COUNTIF('외운 것'!C2:C271,B8)/30} -> 0
B9: 46093 | C9: {=COUNTIF('문장'!J2:J724,B9)} -> 0 | D9: {=COUNTIF('외운 것'!C2:C271,B9)/30} -> 0
B10: 46094 | C10: {=COUNTIF('문장'!J2:J724,B10)} -> 0 | D10: {=COUNTIF('외운 것'!C2:C271,B10)/30} -> 0
B11: 46095 | C11: {=COUNTIF('문장'!J2:J724,B11)} -> 0 | D11: {=COUNTIF('외운 것'!C2:C271,B11)/30} -> 0
B12: 46096 | C12: {=COUNTIF('문장'!J2:J724,B12)} -> 0 | D12: {=COUNTIF('외운 것'!C2:C271,B12)/30} -> 0
B13: 46097 | C13: {=COUNTIF('문장'!J2:J724,B13)} -> 0 | D13: {=COUNTIF('외운 것'!C2:C271,B13)/30} -> 0
B14: 46098 | C14: {=COUNTIF('문장'!J2:J724,B14)} -> 0 | D14: {=COUNTIF('외운 것'!C2:C271,B14)/30} -> 0
B15: 46099 | C15: {=COUNTIF('문장'!J2:J724,B15)} -> 0 | D15: {=COUNTIF('외운 것'!C2:C271,B15)/30} -> 0
B16: 46100 | C16: {=COUNTIF('문장'!J2:J724,B16)} -> 0 | D16: {=COUNTIF('외운 것'!C2:C271,B16)/30} -> 0
B17: 46101 | C17: {=COUNTIF('문장'!J2:J724,B17)} -> 0 | D17: {=COUNTIF('외운 것'!C2:C271,B17)/30} -> 0
B18: 46102 | C18: {=COUNTIF('문장'!J2:J724,B18)} -> 0 | D18: {=COUNTIF('외운 것'!C2:C271,B18)/30} -> 0
B19: 46103 | C19: {=COUNTIF('문장'!J2:J724,B19)} -> 0 | D19: {=COUNTIF('외운 것'!C2:C271,B19)/30} -> 0
B20: 46104 | C20: {=COUNTIF('문장'!J2:J724,B20)} -> 0 | D20: {=COUNTIF('외운 것'!C2:C271,B20)/30} -> 0
B21: 46105 | C21: {=COUNTIF('문장'!J2:J724,B21)} -> 0 | D21: {=COUNTIF('외운 것'!C2:C271,B21)/30} -> 0
B22: 46106 | C22: {=COUNTIF('문장'!J2:J724,B22)} -> 0 | D22: {=COUNTIF('외운 것'!C2:C271,B22)/30} -> 0
B23: 46107 | C23: {=COUNTIF('문장'!J2:J724,B23)} -> 0 | D23: {=COUNTIF('외운 것'!C2:C271,B23)/30} -> 0
B24: 46108 | C24: {=COUNTIF('문장'!J2:J724,B24)} -> 0 | D24: {=COUNTIF('외운 것'!C2:C271,B24)/30} -> 0
B25: 46109 | C25: {=COUNTIF('문장'!J2:J724,B25)} -> 0 | D25: {=COUNTIF('외운 것'!C2:C271,B25)/30} -> 0
B26: 46110 | C26: {=COUNTIF('문장'!J2:J724,B26)} -> 0 | D26: {=COUNTIF('외운 것'!C2:C271,B26)/30} -> 0
B27: 46111 | C27: {=COUNTIF('문장'!J2:J724,B27)} -> 0 | D27: {=COUNTIF('외운 것'!C2:C271,B27)/30} -> 0
B28: 46112 | C28: {=COUNTIF('문장'!J2:J724,B28)} -> 0 | D28: {=COUNTIF('외운 것'!C2:C271,B28)/30} -> 0
A29: 46113 | C29: =SUM(C30:C59) -> 109
B30: 46113 | C30: {=COUNTIF('문장'!J2:J724,B30)} -> 0 | D30: {=COUNTIF('외운 것'!C2:C271,B30)/30} -> 0
B31: 46114 | C31: {=COUNTIF('문장'!J2:J724,B31)} -> 0 | D31: {=COUNTIF('외운 것'!C2:C271,B31)/30} -> 0
B32: 46115 | C32: {=COUNTIF('문장'!J2:J724,B32)} -> 0 | D32: {=COUNTIF('외운 것'!C2:C271,B32)/30} -> 0
B33: 46116 | C33: {=COUNTIF('문장'!J2:J724,B33)} -> 0 | D33: {=COUNTIF('외운 것'!C2:C271,B33)/30} -> 0
B34: 46117 | C34: {=COUNTIF('문장'!J2:J724,B34)} -> 0 | D34: {=COUNTIF('외운 것'!C2:C271,B34)/30} -> 0
B35: 46118 | C35: {=COUNTIF('문장'!J2:J724,B35)} -> 0 | D35: {=COUNTIF('외운 것'!C2:C271,B35)/30} -> 0
B36: 46119 | C36: {=COUNTIF('문장'!J2:J724,B36)} -> 0 | D36: {=COUNTIF('외운 것'!C2:C271,B36)/30} -> 0
B37: 46120 | C37: {=COUNTIF('문장'!J2:J724,B37)} -> 0 | D37: {=COUNTIF('외운 것'!C2:C271,B37)/30} -> 0
B38: 46121 | C38: {=COUNTIF('문장'!J2:J724,B38)} -> 0 | D38: {=COUNTIF('외운 것'!C2:C271,B38)/30} -> 0
B39: 46122 | C39: {=COUNTIF('문장'!J2:J724,B39)} -> 0 | D39: {=COUNTIF('외운 것'!C2:C271,B39)/30} -> 0
B40: 46123 | C40: {=COUNTIF('문장'!J2:J724,B40)} -> 0 | D40: {=COUNTIF('외운 것'!C2:C271,B40)/30} -> 0
...

Sheet 총괄 - 전체
A1: 전체
A2: 구분 | B2: 외운갯수 | C2: Skip | D2: 남은갯수
A3: 1차 | B3: {=COUNTIF('문장'!N2:N724,">=3")-C3} -> 0 | C3: {=COUNTIF('문장'!K2:K724,"1차")} -> 204 | D3: {=COUNTA('문장'!A2:A724)-B3-C3} -> 519
A4: 2차 | B4: {=COUNTIF('문장'!O2:O724,">=3")-C4} -> 324 | C4: {=COUNTIF('문장'!L2:L724,"2차")} -> 399 | D4: {=COUNTA('문장'!A2:A724)-B4-C4} -> 0
A5: 3차 | B5: {=COUNTIF('문장'!H2:H724,">=3")-C5} -> 109 | C5: {=COUNTIF('문장'!M2:M724,"3차")} -> 518 | D5: {=COUNTA('문장'!A2:A724)-B5-C5} -> 96

Sheet 총괄 - 틀린 것 복습
A1: 틀린 것 복습
A2: 틀린것 | B2: 영어 | C2: 외운것2차 | D2: sNo(전체 항목 세기)
A3: 2 | D3: 9
A4: 1 | D4: 32

Sheet 총괄 - 통계
A1: 통계
A2: 틀린것 | B2: 날짜 | C2: sNo(전체 항목 세기)
A3: 1 | C3: 39
A4: 2 | C4: 16
A5: 3 | C5: 7
A6: 4 | C6: 3
A7: 5 | C7: 1
A8: 6 | C8: 1
