Workbook

Sheet 어휘 - 표 1 스냅샷
A1: No | B1: 영어단어 | C1: 어원 | D1: 구분 | E1: 발음 | F1: 힌트 | G1: 뜻 | H1: 문장 | I1: 영어문장 | J1: 외운것 | K1: 틀린것 | L1: 날짜
A2: 1 | B2: ball | C2: ball | D2: ball | E2: [bɔːl] | F2: 부풀어 오르다(b) 모든(all) 면이 그렇게 생긴 것은 ‘공’ | G2: 공 | H2: The children played with a colorful ball in the park. | I2: {=SUBSTITUTE(H2,B2,"( )")} -> The children played with a colorful ( ) in the park. | J2: {=SUMIF('외운 것 - 엑셀다운로드 파일(붙여넣기)'!A3:A562,A2,'외운 것 - 엑셀다운로드 파일(붙여넣기)'!D3:D562)} -> 3 | K2: {=_xlfn.COUNTIFS('외운 것 - 엑셀다운로드 파일(붙여넣기)'!A3:A562,A2,'외운 것 - 엑셀다운로드 파일(붙여넣기)'!D3:D562,0)} -> 0 | L2: {=IF(J2>=3,_xlfn.XLOOKUP(A2,'외운 것 - 엑셀다운로드 파일(붙여넣기)'!A3:A562,'외운 것 - 엑셀다운로드 파일(붙여넣기)'!C3:C562,0,-1),0)} -> 2026-03-14
A3: 2 | B3: balloon | C3: ball | D3: ball | E3: [bəlúːn] | F3: 부풀어 오른 공(ball)이 나중에 아래(oo-u)로 바람이 빠져 나오면 없어지는(n) 것 ‘풍선, 기구’ | G3: 풍선, 기구 | H3: She bought a red balloon for her birthday party. | I3: {=SUBSTITUTE(H3,B3,"( )")} -> She bought a red ( ) for her birthday party. | J3: {=SUMIF('외운 것 - 엑셀다운로드 파일(붙여넣기)'!A3:A562,A3,'외운 것 - 엑셀다운로드 파일(붙여넣기)'!D3:D562)} -> 3 | K3: {=_xlfn.COUNTIFS('외운 것 - 엑셀다운로드 파일(붙여넣기)'!A3:A562,A3,'외운 것 - 엑셀다운로드 파일(붙여넣기)'!D3:D562,0)} -> 1 | L3: {=IF(J3>=3,_xlfn.XLOOKUP(A3,'외운 것 - 엑셀다운로드 파일(붙여넣기)'!A3:A562,'외운 것 - 엑셀다운로드 파일(붙여넣기)'!C3:C562,0,-1),0)} -> 2026-03-16
A4: 3 | B4: bell | C4: bell | D4: bell | E4: [bel] | F4: 공처럼 불룩한(b) 모양의 ‘종, 벨’ | G4: 종, 벨 | H4: The school bell rang to signal the end of class. | I4: {=SUBSTITUTE(H4,B4,"( )")} -> The school ( ) rang to signal the end of class. | J4: {=SUMIF('외운 것 - 엑셀다운로드 파일(붙여넣기)'!A3:A562,A4,'외운 것 - 엑셀다운로드 파일(붙여넣기)'!D3:D562)} -> 3 | K4: {=_xlfn.COUNTIFS('외운 것 - 엑셀다운로드 파일(붙여넣기)'!A3:A562,A4,'외운 것 - 엑셀다운로드 파일(붙여넣기)'!D3:D562,0)} -> 0 | L4: {=IF(J4>=3,_xlfn.XLOOKUP(A4,'외운 것 - 엑셀다운로드 파일(붙여넣기)'!A3:A562,'외운 것 - 엑셀다운로드 파일(붙여넣기)'!C3:C562,0,-1),0)} -> 2026-03-14
A5: 4 | B5: belly | C5: bell | D5: bell | E5: [béli] | F5: 불룩한 bell에 확장을 의미하는 y가 더해저서 더욱더 불룩한 모습이 되는 ‘불룩한 배’ | G5: 불룩한 배 | H5: The cat's belly was soft and warm. | I5: {=SUBSTITUTE(H5,B5,"( )")} -> The cat's ( ) was soft and warm. | J5: {=SUMIF('외운 것 - 엑셀다운로드 파일(붙여넣기)'!A3:A562,A5,'외운 것 - 엑셀다운로드 파일(붙여넣기)'!D3:D562)} -> 3 | K5: {=_xlfn.COUNTIFS('외운 것 - 엑셀다운로드 파일(붙여넣기)'!A3:A562,A5,'외운 것 - 엑셀다운로드 파일(붙여넣기)'!D3:D562,0)} -> 0 | L5: {=IF(J5>=3,_xlfn.XLOOKUP(A5,'외운 것 - 엑셀다운로드 파일(붙여넣기)'!A3:A562,'외운 것 - 엑셀다운로드 파일(붙여넣기)'!C3:C562,0,-1),0)} -> 2026-03-14
A6: 5 | B6: bullet | C6: ball | D6: ball | E6: [búlit] | F6: 처음에 공(ball)처럼 생긴 작은 덩어리(let)였던 ‘총알’ | G6: 총알 | H6: The detective found a bullet at the crime scene. | I6: {=SUBSTITUTE(H6,B6,"( )")} -> The detective found a ( ) at the crime scene. | J6: {=SUMIF('외운 것 - 엑셀다운로드 파일(붙여넣기)'!A3:A562,A6,'외운 것 - 엑셀다운로드 파일(붙여넣기)'!D3:D562)} -> 3 | K6: {=_xlfn.COUNTIFS('외운 것 - 엑셀다운로드 파일(붙여넣기)'!A3:A562,A6,'외운 것 - 엑셀다운로드 파일(붙여넣기)'!D3:D562,0)} -> 0 | L6: {=IF(J6>=3,_xlfn.XLOOKUP(A6,'외운 것 - 엑셀다운로드 파일(붙여넣기)'!A3:A562,'외운 것 - 엑셀다운로드 파일(붙여넣기)'!C3:C562,0,-1),0)} -> 2026-03-14
A7: 6 | B7: bulb | C7: ball | D7: ball | E7: [bʌlb] | F7: 공(ball)처럼 부풀어 오르는(b) ‘둥근 뿌리, 전구’ | G7: 둥근 뿌리, 전구 | H7: I need to replace the light bulb in the kitchen. | I7: {=SUBSTITUTE(H7,B7,"( )")} -> I need to replace the light ( ) in the kitchen. | J7: {=SUMIF('외운 것 - 엑셀다운로드 파일(붙여넣기)'!A3:A562,A7,'외운 것 - 엑셀다운로드 파일(붙여넣기)'!D3:D562)} -> 3 | K7: {=_xlfn.COUNTIFS('외운 것 - 엑셀다운로드 파일(붙여넣기)'!A3:A562,A7,'외운 것 - 엑셀다운로드 파일(붙여넣기)'!D3:D562,0)} -> 0 | L7: {=IF(J7>=3,_xlfn.XLOOKUP(A7,'외운 것 - 엑셀다운로드 파일(붙여넣기)'!A3:A562,'외운 것 - 엑셀다운로드 파일(붙여넣기)'!C3:C562,0,-1),0)} -> 2026-03-14
A8: 7 | B8: bulk | C8: ball | D8: ball | E8: [bʌlk] | F8: 공(ball)처럼 몸이 부풀어오르고 확장(k)되니 ‘큰 규모, 육중한 것’ | G8: 큰 규모, 육중한 것 | H8: He bought rice in bulk to save money. | I8: {=SUBSTITUTE(H8,B8,"( )")} -> He bought rice in ( ) to save money. | J8: {=SUMIF('외운 것 - 엑셀다운로드 파일(붙여넣기)'!A3:A562,A8,'외운 것 - 엑셀다운로드 파일(붙여넣기)'!D3:D562)} -> 3 | K8: {=_xlfn.COUNTIFS('외운 것 - 엑셀다운로드 파일(붙여넣기)'!A3:A562,A8,'외운 것 - 엑셀다운로드 파일(붙여넣기)'!D3:D562,0)} -> 0 | L8: {=IF(J8>=3,_xlfn.XLOOKUP(A8,'외운 것 - 엑셀다운로드 파일(붙여넣기)'!A3:A562,'외운 것 - 엑셀다운로드 파일(붙여넣기)'!C3:C562,0,-1),0)} -> 2026-03-14
A9: 8 | B9: base | C9: base | D9: base | E9: [beis] | F9: 불룩(b)한데 잘 보이지 않는(s) 곳에 있는 ‘바닥, 기초, 기지’ | G9: 바닥, 기초, 기지 | H9: The military base is located near the mountain. | I9: {=SUBSTITUTE(H9,B9,"( )")} -> The military ( ) is located near the mountain. | J9: {=SUMIF('외운 것 - 엑셀다운로드 파일(붙여넣기)'!A3:A562,A9,'외운 것 - 엑셀다운로드 파일(붙여넣기)'!D3:D562)} -> 3 | K9: {=_xlfn.COUNTIFS('외운 것 - 엑셀다운로드 파일(붙여넣기)'!A3:A562,A9,'외운 것 - 엑셀다운로드 파일(붙여넣기)'!D3:D562,0)} -> 0 | L9: {=IF(J9>=3,_xlfn.XLOOKUP(A9,'외운 것 - 엑셀다운로드 파일(붙여넣기)'!A3:A562,'외운 것 - 엑셀다운로드 파일(붙여넣기)'!C3:C562,0,-1),0)} -> 2026-03-14
A10: 9 | B10: basic | C10: base | D10: base | E10: [béisik] | F10: 기초, 바닥(base)의 상태(~ic)이므로 ‘기초적인, 근본적인’ | G10: 기초적인, 근본적인 | H10: You need to learn the basic principles of mathematics. | I10: {=SUBSTITUTE(H10,B10,"( )")} -> You need to learn the ( ) principles of mathematics. | J10: {=SUMIF('외운 것 - 엑셀다운로드 파일(붙여넣기)'!A3:A562,A10,'외운 것 - 엑셀다운로드 파일(붙여넣기)'!D3:D562)} -> 3 | K10: {=_xlfn.COUNTIFS('외운 것 - 엑셀다운로드 파일(붙여넣기)'!A3:A562,A10,'외운 것 - 엑셀다운로드 파일(붙여넣기)'!D3:D562,0)} -> 0 | L10: {=IF(J10>=3,_xlfn.XLOOKUP(A10,'외운 것 - 엑셀다운로드 파일(붙여넣기)'!A3:A562,'외운 것 - 엑셀다운로드 파일(붙여넣기)'!C3:C562,0,-1),0)} -> 2026-03-14
A11: 10 | B11: basement | C11: base | D11: base | E11: [béismənt] | F11: 건물의 기초(base)에 해당하는 ‘지하층, 지하실’ | G11: 지하층, 지하실 | H11: We store old furniture in our basement. | I11: {=SUBSTITUTE(H11,B11,"( )")} -> We store old furniture in our ( ). | J11: {=SUMIF('외운 것 - 엑셀다운로드 파일(붙여넣기)'!A3:A562,A11,'외운 것 - 엑셀다운로드 파일(붙여넣기)'!D3:D562)} -> 3 | K11: {=_xlfn.COUNTIFS('외운 것 - 엑셀다운로드 파일(붙여넣기)'!A3:A562,A11,'외운 것 - 엑셀다운로드 파일(붙여넣기)'!D3:D562,0)} -> 0 | L11: {=IF(J11>=3,_xlfn.XLOOKUP(A11,'외운 것 - 엑셀다운로드 파일(붙여넣기)'!A3:A562,'외운 것 - 엑셀다운로드 파일(붙여넣기)'!C3:C562,0,-1),0)} -> 2026-03-14
A12: 11 | B12: baseball | C12: base | D12: base | E12: [béisbɔ̀ːl] | F12: 1루, 2루, 3루에 둔 base(바닥)을 밟으며 ball(공)로 하는 경기, ‘야구’ | G12: 야구 | H12: My brother plays baseball every weekend. | I12: {=SUBSTITUTE(H12,B12,"( )")} -> My brother plays ( ) every weekend. | J12: {=SUMIF('외운 것 - 엑셀다운로드 파일(붙여넣기)'!A3:A562,A12,'외운 것 - 엑셀다운로드 파일(붙여넣기)'!D3:D562)} -> 3 | K12: {=_xlfn.COUNTIFS('외운 것 - 엑셀다운로드 파일(붙여넣기)'!A3:A562,A12,'외운 것 - 엑셀다운로드 파일(붙여넣기)'!D3:D562,0)} -> 0 | L12: {=IF(J12>=3,_xlfn.XLOOKUP(A12,'외운 것 - 엑셀다운로드 파일(붙여넣기)'!A3:A562,'외운 것 - 엑셀다운로드 파일(붙여넣기)'!C3:C562,0,-1),0)} -> 2026-03-14
A13: 12 | B13: bass | C13: base | D13: base | E13: [beis] | F13: 음악의 여러 파트 중에서 낮은(bass 바닥)음을 차지하는 ‘베이스, 저음’ | G13: 베이스, 저음 | H13: The bass guitar creates deep, low sounds in the band. | I13: {=SUBSTITUTE(H13,B13,"( )")} -> The ( ) guitar creates deep, low sounds in the band. | J13: {=SUMIF('외운 것 - 엑셀다운로드 파일(붙여넣기)'!A3:A562,A13,'외운 것 - 엑셀다운로드 파일(붙여넣기)'!D3:D562)} -> 3 | K13: {=_xlfn.COUNTIFS('외운 것 - 엑셀다운로드 파일(붙여넣기)'!A3:A562,A13,'외운 것 - 엑셀다운로드 파일(붙여넣기)'!D3:D562,0)} -> 0 | L13: {=IF(J13>=3,_xlfn.XLOOKUP(A13,'외운 것 - 엑셀다운로드 파일(붙여넣기)'!A3:A562,'외운 것 - 엑셀다운로드 파일(붙여넣기)'!C3:C562,0,-1),0)} -> 2026-03-14
A14: 13 | B14: blouse | C14: bl | D14: bl | E14: [blaus, blauz] | F14: (허리띠 윗 부분에서) 불룩해지고(b) 늘어진(l) 스타일의 옷, ‘블라우스’ | G14: 블라우스 | H14: She wore a silk blouse to the interview. | I14: {=SUBSTITUTE(H14,B14,"( )")} -> She wore a silk ( ) to the interview. | J14: {=SUMIF('외운 것 - 엑셀다운로드 파일(붙여넣기)'!A3:A562,A14,'외운 것 - 엑셀다운로드 파일(붙여넣기)'!D3:D562)} -> 3 | K14: {=_xlfn.COUNTIFS('외운 것 - 엑셀다운로드 파일(붙여넣기)'!A3:A562,A14,'외운 것 - 엑셀다운로드 파일(붙여넣기)'!D3:D562,0)} -> 0 | L14: {=IF(J14>=3,_xlfn.XLOOKUP(A14,'외운 것 - 엑셀다운로드 파일(붙여넣기)'!A3:A562,'외운 것 - 엑셀다운로드 파일(붙여넣기)'!C3:C562,0,-1),0)} -> 2026-03-14
A15: 14 | B15: bloat | C15: bl | D15: bl | E15: [blout] | F15: 부풀어(bl) 둥근(o) 모양이 한점(at) 생기니 ‘부풀다(붓다)’ | G15: 부풀다(붓다) | H15: Eating too fast can cause your stomach to bloat. | I15: {=SUBSTITUTE(H15,B15,"( )")} -> Eating too fast can cause your stomach to ( ). | J15: {=SUMIF('외운 것 - 엑셀다운로드 파일(붙여넣기)'!A3:A562,A15,'외운 것 - 엑셀다운로드 파일(붙여넣기)'!D3:D562)} -> 3 | K15: {=_xlfn.COUNTIFS('외운 것 - 엑셀다운로드 파일(붙여넣기)'!A3:A562,A15,'외운 것 - 엑셀다운로드 파일(붙여넣기)'!D3:D562,0)} -> 0 | L15: {=IF(J15>=3,_xlfn.XLOOKUP(A15,'외운 것 - 엑셀다운로드 파일(붙여넣기)'!A3:A562,'외운 것 - 엑셀다운로드 파일(붙여넣기)'!C3:C562,0,-1),0)} -> 2026-03-14
A16: 15 | B16: blow | C16: bl | D16: bl | E16: [blou] | F16: 부풀려진(bl) 둥근(o) 입에서 바람(w)을 ‘불다’ | G16: 불다 | H16: The wind will blow strongly tonight. | I16: {=SUBSTITUTE(H16,B16,"( )")} -> The wind will ( ) strongly tonight. | J16: {=SUMIF('외운 것 - 엑셀다운로드 파일(붙여넣기)'!A3:A562,A16,'외운 것 - 엑셀다운로드 파일(붙여넣기)'!D3:D562)} -> 3 | K16: {=_xlfn.COUNTIFS('외운 것 - 엑셀다운로드 파일(붙여넣기)'!A3:A562,A16,'외운 것 - 엑셀다운로드 파일(붙여넣기)'!D3:D562,0)} -> 0 | L16: {=IF(J16>=3,_xlfn.XLOOKUP(A16,'외운 것 - 엑셀다운로드 파일(붙여넣기)'!A3:A562,'외운 것 - 엑셀다운로드 파일(붙여넣기)'!C3:C562,0,-1),0)} -> 2026-03-14
A17: 16 | B17: blowfish | C17: bl > blow | D17: bl | E17: [blóufìꭍ] | F17: 바람을 부는(blow) 것처럼 몸이 부푼 모습의 불고기(fish), ‘복어’ | G17: 복어 | H17: The blowfish can expand to twice its normal size. | I17: {=SUBSTITUTE(H17,B17,"( )")} -> The ( ) can expand to twice its normal size. | J17: {=SUMIF('외운 것 - 엑셀다운로드 파일(붙여넣기)'!A3:A562,A17,'외운 것 - 엑셀다운로드 파일(붙여넣기)'!D3:D562)} -> 3 | K17: {=_xlfn.COUNTIFS('외운 것 - 엑셀다운로드 파일(붙여넣기)'!A3:A562,A17,'외운 것 - 엑셀다운로드 파일(붙여넣기)'!D3:D562,0)} -> 0 | L17: {=IF(J17>=3,_xlfn.XLOOKUP(A17,'외운 것 - 엑셀다운로드 파일(붙여넣기)'!A3:A562,'외운 것 - 엑셀다운로드 파일(붙여넣기)'!C3:C562,0,-1),0)} -> 2026-03-14
A18: 17 | B18: blister | C18: bl | D18: bl | E18: [blístər] | F18: 부풀고(bl) 안에(i) 물이 있어 피부가 서 있는(st) 것처럼 보이는 ‘물집’ | G18: 물집 | H18: I got a blister on my heel from my new shoes. | I18: {=SUBSTITUTE(H18,B18,"( )")} -> I got a ( ) on my heel from my new shoes. | J18: {=SUMIF('외운 것 - 엑셀다운로드 파일(붙여넣기)'!A3:A562,A18,'외운 것 - 엑셀다운로드 파일(붙여넣기)'!D3:D562)} -> 3 | K18: {=_xlfn.COUNTIFS('외운 것 - 엑셀다운로드 파일(붙여넣기)'!A3:A562,A18,'외운 것 - 엑셀다운로드 파일(붙여넣기)'!D3:D562,0)} -> 0 | L18: {=IF(J18>=3,_xlfn.XLOOKUP(A18,'외운 것 - 엑셀다운로드 파일(붙여넣기)'!A3:A562,'외운 것 - 엑셀다운로드 파일(붙여넣기)'!C3:C562,0,-1),0)} -> 2026-03-14
A19: 18 | B19: blur | C19: bl | D19: bl | E19: [bləːr] | F19: 눈꺼풀이부풀어(bl) 올라 시력이 아래로(u) 바닥이 되고 보려면 눈에 힘(r)도 많이 들어가니, ‘흐릿해지다’ | G19: 흐릿해지다 | H19: Her vision became a blur without her glasses. | I19: {=SUBSTITUTE(H19,B19,"( )")} -> Her vision became a ( ) without her glasses. | J19: {=SUMIF('외운 것 - 엑셀다운로드 파일(붙여넣기)'!A3:A562,A19,'외운 것 - 엑셀다운로드 파일(붙여넣기)'!D3:D562)} -> 3 | K19: {=_xlfn.COUNTIFS('외운 것 - 엑셀다운로드 파일(붙여넣기)'!A3:A562,A19,'외운 것 - 엑셀다운로드 파일(붙여넣기)'!D3:D562,0)} -> 0 | L19: {=IF(J19>=3,_xlfn.XLOOKUP(A19,'외운 것 - 엑셀다운로드 파일(붙여넣기)'!A3:A562,'외운 것 - 엑셀다운로드 파일(붙여넣기)'!C3:C562,0,-1),0)} -> 2026-03-14
A20: 19 | B20: blind | C20: bl | D20: bl | E20: [blaind] | F20: 눈꺼풀이 부풀어(bl) 올라 안에(i) 있는 시력을 없어지니(n) ‘눈이 먼’ | G20: 눈이 먼 | H20: The blind man navigated with his white cane. | I20: {=SUBSTITUTE(H20,B20,"( )")} -> The ( ) man navigated with his white cane. | J20: {=SUMIF('외운 것 - 엑셀다운로드 파일(붙여넣기)'!A3:A562,A20,'외운 것 - 엑셀다운로드 파일(붙여넣기)'!D3:D562)} -> 3 | K20: {=_xlfn.COUNTIFS('외운 것 - 엑셀다운로드 파일(붙여넣기)'!A3:A562,A20,'외운 것 - 엑셀다운로드 파일(붙여넣기)'!D3:D562,0)} -> 0 | L20: {=IF(J20>=3,_xlfn.XLOOKUP(A20,'외운 것 - 엑셀다운로드 파일(붙여넣기)'!A3:A562,'외운 것 - 엑셀다운로드 파일(붙여넣기)'!C3:C562,0,-1),0)} -> 2026-03-14
A21: 20 | B21: bluff | C21: bl | D21: bl | E21: [blʌf] | F21: 사실을 부풀려(bl)서 수준이 낮고(u) 내용은 가벼운(ff) ‘허풍’ | G21: 허풍 | H21: His bluff didn't work because everyone knew he was lying. | I21: {=SUBSTITUTE(H21,B21,"( )")} -> His ( ) didn't work because everyone knew he was lying. | J21: {=SUMIF('외운 것 - 엑셀다운로드 파일(붙여넣기)'!A3:A562,A21,'외운 것 - 엑셀다운로드 파일(붙여넣기)'!D3:D562)} -> 3 | K21: {=_xlfn.COUNTIFS('외운 것 - 엑셀다운로드 파일(붙여넣기)'!A3:A562,A21,'외운 것 - 엑셀다운로드 파일(붙여넣기)'!D3:D562,0)} -> 0 | L21: {=IF(J21>=3,_xlfn.XLOOKUP(A21,'외운 것 - 엑셀다운로드 파일(붙여넣기)'!A3:A562,'외운 것 - 엑셀다운로드 파일(붙여넣기)'!C3:C562,0,-1),0)} -> 2026-03-14
A22: 21 | B22: bubble | C22: bu | D22: bu | E22: [bΛbl] | F22: 부풀어(b) 아래에서(u) 올라오며 계속 부풀어(bb) 오르는 ‘거품’ | G22: 거품 | H22: The child laughed as she blew a large soap bubble. | I22: {=SUBSTITUTE(H22,B22,"( )")} -> The child laughed as she blew a large soap ( ). | J22: {=SUMIF('외운 것 - 엑셀다운로드 파일(붙여넣기)'!A3:A562,A22,'외운 것 - 엑셀다운로드 파일(붙여넣기)'!D3:D562)} -> 3 | K22: {=_xlfn.COUNTIFS('외운 것 - 엑셀다운로드 파일(붙여넣기)'!A3:A562,A22,'외운 것 - 엑셀다운로드 파일(붙여넣기)'!D3:D562,0)} -> 0 | L22: {=IF(J22>=3,_xlfn.XLOOKUP(A22,'외운 것 - 엑셀다운로드 파일(붙여넣기)'!A3:A562,'외운 것 - 엑셀다운로드 파일(붙여넣기)'!C3:C562,0,-1),0)} -> 2026-03-14
A23: 22 | B23: bud | C23: bu | D23: bu | E23: [bʌd] | F23: 부풀어 오르지만(bu) 아직 성장이 저하된(d) ‘싹, 꽃봉오리’ | G23: 싹, 꽃봉오리 | H23: The flower bud will soon bloom in spring. | I23: {=SUBSTITUTE(H23,B23,"( )")} -> The flower ( ) will soon bloom in spring. | J23: {=SUMIF('외운 것 - 엑셀다운로드 파일(붙여넣기)'!A3:A562,A23,'외운 것 - 엑셀다운로드 파일(붙여넣기)'!D3:D562)} -> 3 | K23: {=_xlfn.COUNTIFS('외운 것 - 엑셀다운로드 파일(붙여넣기)'!A3:A562,A23,'외운 것 - 엑셀다운로드 파일(붙여넣기)'!D3:D562,0)} -> 0 | L23: {=IF(J23>=3,_xlfn.XLOOKUP(A23,'외운 것 - 엑셀다운로드 파일(붙여넣기)'!A3:A562,'외운 것 - 엑셀다운로드 파일(붙여넣기)'!C3:C562,0,-1),0)} -> 2026-03-14
A24: 23 | B24: budget | C24: bu > bud | D24: bu | E24: [bΛdʒit] | F24: 싹(bud)을 틔우기 위해 가지는(get) ‘예산’ | G24: 예산 | H24: We need to create a budget for our vacation. | I24: {=SUBSTITUTE(H24,B24,"( )")} -> We need to create a ( ) for our vacation. | J24: {=SUMIF('외운 것 - 엑셀다운로드 파일(붙여넣기)'!A3:A562,A24,'외운 것 - 엑셀다운로드 파일(붙여넣기)'!D3:D562)} -> 3 | K24: {=_xlfn.COUNTIFS('외운 것 - 엑셀다운로드 파일(붙여넣기)'!A3:A562,A24,'외운 것 - 엑셀다운로드 파일(붙여넣기)'!D3:D562,0)} -> 1 | L24: {=IF(J24>=3,_xlfn.XLOOKUP(A24,'외운 것 - 엑셀다운로드 파일(붙여넣기)'!A3:A562,'외운 것 - 엑셀다운로드 파일(붙여넣기)'!C3:C562,0,-1),0)} -> 2026-03-16
A25: 24 | B25: bun | C25: bu | D25: bu | E25: [bʌn] | F25: 부풀어 오른(bu) 작은(n) 빵, ‘동그랗고 작은 빵’ | G25: 동그랗고 작은 빵 | H25: She tied her hair in a neat bun for the dance recital. | I25: {=SUBSTITUTE(H25,B25,"( )")} -> She tied her hair in a neat ( ) for the dance recital. | J25: {=SUMIF('외운 것 - 엑셀다운로드 파일(붙여넣기)'!A3:A562,A25,'외운 것 - 엑셀다운로드 파일(붙여넣기)'!D3:D562)} -> 3 | K25: {=_xlfn.COUNTIFS('외운 것 - 엑셀다운로드 파일(붙여넣기)'!A3:A562,A25,'외운 것 - 엑셀다운로드 파일(붙여넣기)'!D3:D562,0)} -> 0 | L25: {=IF(J25>=3,_xlfn.XLOOKUP(A25,'외운 것 - 엑셀다운로드 파일(붙여넣기)'!A3:A562,'외운 것 - 엑셀다운로드 파일(붙여넣기)'!C3:C562,0,-1),0)} -> 2026-03-14
A26: 25 | B26: bunch | C26: bu > bun | D26: bu | E26: [bʌnʧ] | F26: 동그랗고 작은 빵(bun) 같은 것들을 잡아서(ch) 만든 ‘다발, (포도 따위의) 송이’ | G26: 다발, (포도 따위의) 송이 | H26: He brought a bunch of red roses for our anniversary. | I26: {=SUBSTITUTE(H26,B26,"( )")} -> He brought a ( ) of red roses for our anniversary. | J26: {=SUMIF('외운 것 - 엑셀다운로드 파일(붙여넣기)'!A3:A562,A26,'외운 것 - 엑셀다운로드 파일(붙여넣기)'!D3:D562)} -> 3 | K26: {=_xlfn.COUNTIFS('외운 것 - 엑셀다운로드 파일(붙여넣기)'!A3:A562,A26,'외운 것 - 엑셀다운로드 파일(붙여넣기)'!D3:D562,0)} -> 0 | L26: {=IF(J26>=3,_xlfn.XLOOKUP(A26,'외운 것 - 엑셀다운로드 파일(붙여넣기)'!A3:A562,'외운 것 - 엑셀다운로드 파일(붙여넣기)'!C3:C562,0,-1),0)} -> 2026-03-14
A27: 26 | B27: buy | C27: bu | D27: bu | E27: [bai] | F27: 자꾸 ‘사다’ 그래서 가방이 부풀어 오르고(bu) 안에 구입한 개수가 확장(y)되어 간다. | G27: 사다 | H27: I want to buy a new computer next month. | I27: {=SUBSTITUTE(H27,B27,"( )")} -> I want to ( ) a new computer next month. | J27: {=SUMIF('외운 것 - 엑셀다운로드 파일(붙여넣기)'!A3:A562,A27,'외운 것 - 엑셀다운로드 파일(붙여넣기)'!D3:D562)} -> 3 | K27: {=_xlfn.COUNTIFS('외운 것 - 엑셀다운로드 파일(붙여넣기)'!A3:A562,A27,'외운 것 - 엑셀다운로드 파일(붙여넣기)'!D3:D562,0)} -> 0 | L27: {=IF(J27>=3,_xlfn.XLOOKUP(A27,'외운 것 - 엑셀다운로드 파일(붙여넣기)'!A3:A562,'외운 것 - 엑셀다운로드 파일(붙여넣기)'!C3:C562,0,-1),0)} -> 2026-03-14
A28: 27 | B28: bury | C28: bu > buy | D28: bu | E28: [béri] | F28: 사서(buy) 세게 힘을(r) 가해 ‘묻어 놓다’ | G28: 묻어 놓다 | H28: They will bury the time capsule in the school yard. | I28: {=SUBSTITUTE(H28,B28,"( )")} -> They will ( ) the time capsule in the school yard. | J28: {=SUMIF('외운 것 - 엑셀다운로드 파일(붙여넣기)'!A3:A562,A28,'외운 것 - 엑셀다운로드 파일(붙여넣기)'!D3:D562)} -> 1 | K28: {=_xlfn.COUNTIFS('외운 것 - 엑셀다운로드 파일(붙여넣기)'!A3:A562,A28,'외운 것 - 엑셀다운로드 파일(붙여넣기)'!D3:D562,0)} -> 4 | L28: {=IF(J28>=3,_xlfn.XLOOKUP(A28,'외운 것 - 엑셀다운로드 파일(붙여넣기)'!A3:A562,'외운 것 - 엑셀다운로드 파일(붙여넣기)'!C3:C562,0,-1),0)} -> 0
A29: 28 | B29: burp | C29: bu | D29: bu | E29: [bəːrp] | F29: 속에서 부풀어 올라오는(bu) 가스의 힘(r)이 밖으로 폭하고(p) 튀어 나오는 ‘트림, 트림소리’ | G29: 트림, 트림소리 | H29: The baby needs to burp after drinking milk. | I29: {=SUBSTITUTE(H29,B29,"( )")} -> The baby needs to ( ) after drinking milk. | J29: {=SUMIF('외운 것 - 엑셀다운로드 파일(붙여넣기)'!A3:A562,A29,'외운 것 - 엑셀다운로드 파일(붙여넣기)'!D3:D562)} -> 3 | K29: {=_xlfn.COUNTIFS('외운 것 - 엑셀다운로드 파일(붙여넣기)'!A3:A562,A29,'외운 것 - 엑셀다운로드 파일(붙여넣기)'!D3:D562,0)} -> 0 | L29: {=IF(J29>=3,_xlfn.XLOOKUP(A29,'외운 것 - 엑셀다운로드 파일(붙여넣기)'!A3:A562,'외운 것 - 엑셀다운로드 파일(붙여넣기)'!C3:C562,0,-1),0)} -> 2026-03-14
A30: 29 | B30: ban | C30: b | D30: ban | E30: [bæn] | F30: 막고(b) 하나(an)도 못 나가게 하니 ‘막다, 금지하다, 금지’ | G30: 막다, 금지하다, 금지 | H30: The school decided to ban mobile phones during class. | I30: {=SUBSTITUTE(H30,B30,"( )")} -> The school decided to ( ) mobile phones during class. | J30: {=SUMIF('외운 것 - 엑셀다운로드 파일(붙여넣기)'!A3:A562,A30,'외운 것 - 엑셀다운로드 파일(붙여넣기)'!D3:D562)} -> 3 | K30: {=_xlfn.COUNTIFS('외운 것 - 엑셀다운로드 파일(붙여넣기)'!A3:A562,A30,'외운 것 - 엑셀다운로드 파일(붙여넣기)'!D3:D562,0)} -> 0 | L30: {=IF(J30>=3,_xlfn.XLOOKUP(A30,'외운 것 - 엑셀다운로드 파일(붙여넣기)'!A3:A562,'외운 것 - 엑셀다운로드 파일(붙여넣기)'!C3:C562,0,-1),0)} -> 2026-03-14
A31: 30 | B31: banish | C31: b > ban | D31: ban | E31: [bǽniʃ] | F31: 들어오는 걸 막고(ban) 보이지(sh) 않도록 ‘추방하다, 몰아내다’ | G31: 추방하다, 몰아내다 | H31: The king will banish anyone who breaks the law. | I31: {=SUBSTITUTE(H31,B31,"( )")} -> The king will ( ) anyone who breaks the law. | J31: {=SUMIF('외운 것 - 엑셀다운로드 파일(붙여넣기)'!A3:A562,A31,'외운 것 - 엑셀다운로드 파일(붙여넣기)'!D3:D562)} -> 3 | K31: {=_xlfn.COUNTIFS('외운 것 - 엑셀다운로드 파일(붙여넣기)'!A3:A562,A31,'외운 것 - 엑셀다운로드 파일(붙여넣기)'!D3:D562,0)} -> 0 | L31: {=IF(J31>=3,_xlfn.XLOOKUP(A31,'외운 것 - 엑셀다운로드 파일(붙여넣기)'!A3:A562,'외운 것 - 엑셀다운로드 파일(붙여넣기)'!C3:C562,0,-1),0)} -> 2026-03-14
A32: 31 | B32: band | C32: b | D32: ban | E32: [bænd] | F32: 터져 나가지 못하게 막으려고(b) 끈을 더하여(and) ‘묶다, 반창고, 띠, 무리’ | G32: 묶다, 반창고, 띠, 무리 | H32: My favorite band is performing at the concert tonight. | I32: {=SUBSTITUTE(H32,B32,"( )")} -> My favorite ( ) is performing at the concert tonight. | J32: {=SUMIF('외운 것 - 엑셀다운로드 파일(붙여넣기)'!A3:A562,A32,'외운 것 - 엑셀다운로드 파일(붙여넣기)'!D3:D562)} -> 3 | K32: {=_xlfn.COUNTIFS('외운 것 - 엑셀다운로드 파일(붙여넣기)'!A3:A562,A32,'외운 것 - 엑셀다운로드 파일(붙여넣기)'!D3:D562,0)} -> 0 | L32: {=IF(J32>=3,_xlfn.XLOOKUP(A32,'외운 것 - 엑셀다운로드 파일(붙여넣기)'!A3:A562,'외운 것 - 엑셀다운로드 파일(붙여넣기)'!C3:C562,0,-1),0)} -> 2026-03-14
A33: 32 | B33: bandit | C33: band | D33: band | E33: [bǽndit] | F33: 묶어 놓고(band) 그것(it)을 달라고 하는 ‘노상강도’ | G33: 노상강도 | H33: The bandit stole money from the stagecoach. | I33: {=SUBSTITUTE(H33,B33,"( )")} -> The ( ) stole money from the stagecoach. | J33: {=SUMIF('외운 것 - 엑셀다운로드 파일(붙여넣기)'!A3:A562,A33,'외운 것 - 엑셀다운로드 파일(붙여넣기)'!D3:D562)} -> 3 | K33: {=_xlfn.COUNTIFS('외운 것 - 엑셀다운로드 파일(붙여넣기)'!A3:A562,A33,'외운 것 - 엑셀다운로드 파일(붙여넣기)'!D3:D562,0)} -> 0 | L33: {=IF(J33>=3,_xlfn.XLOOKUP(A33,'외운 것 - 엑셀다운로드 파일(붙여넣기)'!A3:A562,'외운 것 - 엑셀다운로드 파일(붙여넣기)'!C3:C562,0,-1),0)} -> 2026-03-14
A34: 33 | B34: husband | C34: band | D34: band | E34: [hΛzbənd] | F34: 집(house)을 끈(band)으로 둘러싸듯 보호하는 사람, ‘남편’ | G34: 남편 | H34: Her husband cooks dinner every Friday night. | I34: {=SUBSTITUTE(H34,B34,"( )")} -> Her ( ) cooks dinner every Friday night. | J34: {=SUMIF('외운 것 - 엑셀다운로드 파일(붙여넣기)'!A3:A562,A34,'외운 것 - 엑셀다운로드 파일(붙여넣기)'!D3:D562)} -> 3 | K34: {=_xlfn.COUNTIFS('외운 것 - 엑셀다운로드 파일(붙여넣기)'!A3:A562,A34,'외운 것 - 엑셀다운로드 파일(붙여넣기)'!D3:D562,0)} -> 2 | L34: {=IF(J34>=3,_xlfn.XLOOKUP(A34,'외운 것 - 엑셀다운로드 파일(붙여넣기)'!A3:A562,'외운 것 - 엑셀다운로드 파일(붙여넣기)'!C3:C562,0,-1),0)} -> 2026-03-17
A35: 34 | B35: abandon | C35: band | D35: band | E35: [əbǽndən] | F35: 하나로(a) 묶어 놓은(band) 것을 없애니(n) ‘포기하다, 버리다’ | G35: 포기하다, 버리다 | H35: The crew had to abandon the sinking ship. | I35: {=SUBSTITUTE(H35,B35,"( )")} -> The crew had to ( ) the sinking ship. | J35: {=SUMIF('외운 것 - 엑셀다운로드 파일(붙여넣기)'!A3:A562,A35,'외운 것 - 엑셀다운로드 파일(붙여넣기)'!D3:D562)} -> 3 | K35: {=_xlfn.COUNTIFS('외운 것 - 엑셀다운로드 파일(붙여넣기)'!A3:A562,A35,'외운 것 - 엑셀다운로드 파일(붙여넣기)'!D3:D562,0)} -> 1 | L35: {=IF(J35>=3,_xlfn.XLOOKUP(A35,'외운 것 - 엑셀다운로드 파일(붙여넣기)'!A3:A562,'외운 것 - 엑셀다운로드 파일(붙여넣기)'!C3:C562,0,-1),0)} -> 2026-03-16
A36: 35 | B36: bandage | C36: band | D36: band | E36: [bǽndidʒ] | F36: 반창고(band)를 오랫동안(age) 감아 놓으려고 만든 것, ‘붕대’ | G36: 붕대 | H36: The nurse put a bandage on my cut. | I36: {=SUBSTITUTE(H36,B36,"( )")} -> The nurse put a ( ) on my cut. | J36: {=SUMIF('외운 것 - 엑셀다운로드 파일(붙여넣기)'!A3:A562,A36,'외운 것 - 엑셀다운로드 파일(붙여넣기)'!D3:D562)} -> 3 | K36: {=_xlfn.COUNTIFS('외운 것 - 엑셀다운로드 파일(붙여넣기)'!A3:A562,A36,'외운 것 - 엑셀다운로드 파일(붙여넣기)'!D3:D562,0)} -> 0 | L36: {=IF(J36>=3,_xlfn.XLOOKUP(A36,'외운 것 - 엑셀다운로드 파일(붙여넣기)'!A3:A562,'외운 것 - 엑셀다운로드 파일(붙여넣기)'!C3:C562,0,-1),0)} -> 2026-03-14
A37: 36 | B37: bind | C37: band | D37: band | E37: [baind] | F37: (band ▶︎ bind) ‘묶다’ | G37: 묶다 | H37: Strong rope will bind the packages together securely. | I37: {=SUBSTITUTE(H37,B37,"( )")} -> Strong rope will ( ) the packages together securely. | J37: {=SUMIF('외운 것 - 엑셀다운로드 파일(붙여넣기)'!A3:A562,A37,'외운 것 - 엑셀다운로드 파일(붙여넣기)'!D3:D562)} -> 3 | K37: {=_xlfn.COUNTIFS('외운 것 - 엑셀다운로드 파일(붙여넣기)'!A3:A562,A37,'외운 것 - 엑셀다운로드 파일(붙여넣기)'!D3:D562,0)} -> 0 | L37: {=IF(J37>=3,_xlfn.XLOOKUP(A37,'외운 것 - 엑셀다운로드 파일(붙여넣기)'!A3:A562,'외운 것 - 엑셀다운로드 파일(붙여넣기)'!C3:C562,0,-1),0)} -> 2026-03-14
A38: 37 | B38: bond | C38: band | D38: band | E38: [band] | F38: 묶어서(band ▶︎ bond) 하나되게 하는 ‘결속, 유대, 접찹제’ | G38: 결속, 유대, 접찹제 | H38: The mother and child share a special bond. | I38: {=SUBSTITUTE(H38,B38,"( )")} -> The mother and child share a special ( ). | J38: {=SUMIF('외운 것 - 엑셀다운로드 파일(붙여넣기)'!A3:A562,A38,'외운 것 - 엑셀다운로드 파일(붙여넣기)'!D3:D562)} -> 3 | K38: {=_xlfn.COUNTIFS('외운 것 - 엑셀다운로드 파일(붙여넣기)'!A3:A562,A38,'외운 것 - 엑셀다운로드 파일(붙여넣기)'!D3:D562,0)} -> 1 | L38: {=IF(J38>=3,_xlfn.XLOOKUP(A38,'외운 것 - 엑셀다운로드 파일(붙여넣기)'!A3:A562,'외운 것 - 엑셀다운로드 파일(붙여넣기)'!C3:C562,0,-1),0)} -> 2026-03-16
A39: 38 | B39: bound | C39: band > bond | D39: band | E39: [baund] | F39: 아래쪽에(u) 넣어두고 묶으니(bond) 이동이 제한되어 생기는 ‘한계, 경계’ | G39: 한계, 경계 | H39: The rabbit bound across the field quickly. | I39: {=SUBSTITUTE(H39,B39,"( )")} -> The rabbit ( ) across the field quickly. | J39: {=SUMIF('외운 것 - 엑셀다운로드 파일(붙여넣기)'!A3:A562,A39,'외운 것 - 엑셀다운로드 파일(붙여넣기)'!D3:D562)} -> 3 | K39: {=_xlfn.COUNTIFS('외운 것 - 엑셀다운로드 파일(붙여넣기)'!A3:A562,A39,'외운 것 - 엑셀다운로드 파일(붙여넣기)'!D3:D562,0)} -> 0 | L39: {=IF(J39>=3,_xlfn.XLOOKUP(A39,'외운 것 - 엑셀다운로드 파일(붙여넣기)'!A3:A562,'외운 것 - 엑셀다운로드 파일(붙여넣기)'!C3:C562,0,-1),0)} -> 2026-03-14
A40: 39 | B40: boundary | C40: band > bond > bound | D40: band | E40: [báundəri] | F40: 국가 사이의 경계(bound)를 더 강화(r)하고 확장(y)하면 생기는 ‘국경, 경계’ | G40: 국경, 경계 | H40: The fence marks the boundary between the two properties. | I40: {=SUBSTITUTE(H40,B40,"( )")} -> The fence marks the ( ) between the two properties. | J40: {=SUMIF('외운 것 - 엑셀다운로드 파일(붙여넣기)'!A3:A562,A40,'외운 것 - 엑셀다운로드 파일(붙여넣기)'!D3:D562)} -> 3 | K40: {=_xlfn.COUNTIFS('외운 것 - 엑셀다운로드 파일(붙여넣기)'!A3:A562,A40,'외운 것 - 엑셀다운로드 파일(붙여넣기)'!D3:D562,0)} -> 0 | L40: {=IF(J40>=3,_xlfn.XLOOKUP(A40,'외운 것 - 엑셀다운로드 파일(붙여넣기)'!A3:A562,'외운 것 - 엑셀다운로드 파일(붙여넣기)'!C3:C562,0,-1),0)} -> 2026-03-14
...

Sheet 외운 것 - 엑셀다운로드 파일(붙여넣기)
A2: No2 | B2: 영어단어2 | C2: 날짜2 | D2: 외운것2 | E2: 비고(numbers) | F2: 순서
A3: 1655 | B3: population | C3: 2026-03-15 | D3: 1 | E3: {=_xlfn.COUNTIFS(B3:B562,B3,D3:D562,1,A3:A562,A3)} -> 1 | F3: {=(YEAR(C3)-2025)*1000+MONTH(C3)*31+DAY(C3)+A3} -> 2763
A4: 1654 | B4: popularity | C4: 2026-03-15 | D4: 1 | E4: {=_xlfn.COUNTIFS(B3:B562,B4,D3:D562,1,A3:A562,A4)} -> 1 | F4: {=(YEAR(C4)-2025)*1000+MONTH(C4)*31+DAY(C4)+A4} -> 2762
A5: 1653 | B5: popular | C5: 2026-03-15 | D5: 3 | E5: {=_xlfn.COUNTIFS(B3:B562,B5,D3:D562,1,A3:A562,A5)} -> 0 | F5: {=(YEAR(C5)-2025)*1000+MONTH(C5)*31+DAY(C5)+A5} -> 2761
A6: 1652 | B6: popsong | C6: 2026-03-15 | D6: 3 | E6: {=_xlfn.COUNTIFS(B3:B562,B6,D3:D562,1,A3:A562,A6)} -> 0 | F6: {=(YEAR(C6)-2025)*1000+MONTH(C6)*31+DAY(C6)+A6} -> 2760
A7: 1651 | B7: popcorn | C7: 2026-03-15 | D7: 3 | E7: {=_xlfn.COUNTIFS(B3:B562,B7,D3:D562,1,A3:A562,A7)} -> 0 | F7: {=(YEAR(C7)-2025)*1000+MONTH(C7)*31+DAY(C7)+A7} -> 2759
A8: 1650 | B8: surplus | C8: 2026-03-15 | D8: 0 | E8: {=_xlfn.COUNTIFS(B3:B562,B8,D3:D562,1,A3:A562,A8)} -> 0 | F8: {=(YEAR(C8)-2025)*1000+MONTH(C8)*31+DAY(C8)+A8} -> 2758
A9: 1649 | B9: plus | C9: 2026-03-15 | D9: 3 | E9: {=_xlfn.COUNTIFS(B3:B562,B9,D3:D562,1,A3:A562,A9)} -> 0 | F9: {=(YEAR(C9)-2025)*1000+MONTH(C9)*31+DAY(C9)+A9} -> 2757
A10: 1648 | B10: monopoly | C10: 2026-03-15 | D10: 1 | E10: {=_xlfn.COUNTIFS(B3:B562,B10,D3:D562,1,A3:A562,A10)} -> 1 | F10: {=(YEAR(C10)-2025)*1000+MONTH(C10)*31+DAY(C10)+A10} -> 2756
A11: 1647 | B11: employee | C11: 2026-03-15 | D11: 1 | E11: {=_xlfn.COUNTIFS(B3:B562,B11,D3:D562,1,A3:A562,A11)} -> 1 | F11: {=(YEAR(C11)-2025)*1000+MONTH(C11)*31+DAY(C11)+A11} -> 2755
A12: 1646 | B12: employer | C12: 2026-03-15 | D12: 1 | E12: {=_xlfn.COUNTIFS(B3:B562,B12,D3:D562,1,A3:A562,A12)} -> 1 | F12: {=(YEAR(C12)-2025)*1000+MONTH(C12)*31+DAY(C12)+A12} -> 2754
A13: 1645 | B13: employ | C13: 2026-03-15 | D13: 0 | E13: {=_xlfn.COUNTIFS(B3:B562,B13,D3:D562,1,A3:A562,A13)} -> 0 | F13: {=(YEAR(C13)-2025)*1000+MONTH(C13)*31+DAY(C13)+A13} -> 2753
A14: 1644 | B14: applicant | C14: 2026-03-15 | D14: 1 | E14: {=_xlfn.COUNTIFS(B3:B562,B14,D3:D562,1,A3:A562,A14)} -> 1 | F14: {=(YEAR(C14)-2025)*1000+MONTH(C14)*31+DAY(C14)+A14} -> 2752
A15: 1643 | B15: apply | C15: 2026-03-15 | D15: 1 | E15: {=_xlfn.COUNTIFS(B3:B562,B15,D3:D562,1,A3:A562,A15)} -> 1 | F15: {=(YEAR(C15)-2025)*1000+MONTH(C15)*31+DAY(C15)+A15} -> 2751
A16: 1642 | B16: reply | C16: 2026-03-15 | D16: 1 | E16: {=_xlfn.COUNTIFS(B3:B562,B16,D3:D562,1,A3:A562,A16)} -> 1 | F16: {=(YEAR(C16)-2025)*1000+MONTH(C16)*31+DAY(C16)+A16} -> 2750
A17: 1641 | B17: comply | C17: 2026-03-15 | D17: 1 | E17: {=_xlfn.COUNTIFS(B3:B562,B17,D3:D562,1,A3:A562,A17)} -> 1 | F17: {=(YEAR(C17)-2025)*1000+MONTH(C17)*31+DAY(C17)+A17} -> 2749
A18: 1640 | B18: accomplish | C18: 2026-03-15 | D18: 0 | E18: {=_xlfn.COUNTIFS(B3:B562,B18,D3:D562,1,A3:A562,A18)} -> 0 | F18: {=(YEAR(C18)-2025)*1000+MONTH(C18)*31+DAY(C18)+A18} -> 2748
A19: 1639 | B19: duplicate | C19: 2026-03-15 | D19: 0 | E19: {=_xlfn.COUNTIFS(B3:B562,B19,D3:D562,1,A3:A562,A19)} -> 0 | F19: {=(YEAR(C19)-2025)*1000+MONTH(C19)*31+DAY(C19)+A19} -> 2747
A20: 1638 | B20: implicate | C20: 2026-03-15 | D20: 0 | E20: {=_xlfn.COUNTIFS(B3:B562,B20,D3:D562,1,A3:A562,A20)} -> 0 | F20: {=(YEAR(C20)-2025)*1000+MONTH(C20)*31+DAY(C20)+A20} -> 2746
A21: 1637 | B21: complicate | C21: 2026-03-15 | D21: 1 | E21: {=_xlfn.COUNTIFS(B3:B562,B21,D3:D562,1,A3:A562,A21)} -> 1 | F21: {=(YEAR(C21)-2025)*1000+MONTH(C21)*31+DAY(C21)+A21} -> 2745
A22: 1636 | B22: complex | C22: 2026-03-15 | D22: 1 | E22: {=_xlfn.COUNTIFS(B3:B562,B22,D3:D562,1,A3:A562,A22)} -> 1 | F22: {=(YEAR(C22)-2025)*1000+MONTH(C22)*31+DAY(C22)+A22} -> 2744
A23: 1635 | B23: implement | C23: 2026-03-15 | D23: 0 | E23: {=_xlfn.COUNTIFS(B3:B562,B23,D3:D562,1,A3:A562,A23)} -> 0 | F23: {=(YEAR(C23)-2025)*1000+MONTH(C23)*31+DAY(C23)+A23} -> 2743
A24: 1634 | B24: supplement | C24: 2026-03-15 | D24: 0 | E24: {=_xlfn.COUNTIFS(B3:B562,B24,D3:D562,1,A3:A562,A24)} -> 0 | F24: {=(YEAR(C24)-2025)*1000+MONTH(C24)*31+DAY(C24)+A24} -> 2742
A25: 1633 | B25: compliment | C25: 2026-03-15 | D25: 0 | E25: {=_xlfn.COUNTIFS(B3:B562,B25,D3:D562,1,A3:A562,A25)} -> 0 | F25: {=(YEAR(C25)-2025)*1000+MONTH(C25)*31+DAY(C25)+A25} -> 2741
A26: 1632 | B26: complement | C26: 2026-03-15 | D26: 0 | E26: {=_xlfn.COUNTIFS(B3:B562,B26,D3:D562,1,A3:A562,A26)} -> 0 | F26: {=(YEAR(C26)-2025)*1000+MONTH(C26)*31+DAY(C26)+A26} -> 2740
A27: 1631 | B27: incomplete | C27: 2026-03-15 | D27: 1 | E27: {=_xlfn.COUNTIFS(B3:B562,B27,D3:D562,1,A3:A562,A27)} -> 1 | F27: {=(YEAR(C27)-2025)*1000+MONTH(C27)*31+DAY(C27)+A27} -> 2739
A28: 1630 | B28: complete | C28: 2026-03-15 | D28: 1 | E28: {=_xlfn.COUNTIFS(B3:B562,B28,D3:D562,1,A3:A562,A28)} -> 1 | F28: {=(YEAR(C28)-2025)*1000+MONTH(C28)*31+DAY(C28)+A28} -> 2738
A29: 1629 | B29: deplete | C29: 2026-03-15 | D29: 1 | E29: {=_xlfn.COUNTIFS(B3:B562,B29,D3:D562,1,A3:A562,A29)} -> 1 | F29: {=(YEAR(C29)-2025)*1000+MONTH(C29)*31+DAY(C29)+A29} -> 2737
A30: 1628 | B30: multiply | C30: 2026-03-15 | D30: 0 | E30: {=_xlfn.COUNTIFS(B3:B562,B30,D3:D562,1,A3:A562,A30)} -> 0 | F30: {=(YEAR(C30)-2025)*1000+MONTH(C30)*31+DAY(C30)+A30} -> 2736
A31: 1627 | B31: multiple | C31: 2026-03-15 | D31: 1 | E31: {=_xlfn.COUNTIFS(B3:B562,B31,D3:D562,1,A3:A562,A31)} -> 1 | F31: {=(YEAR(C31)-2025)*1000+MONTH(C31)*31+DAY(C31)+A31} -> 2735
A32: 1626 | B32: plenty | C32: 2026-03-15 | D32: 1 | E32: {=_xlfn.COUNTIFS(B3:B562,B32,D3:D562,1,A3:A562,A32)} -> 1 | F32: {=(YEAR(C32)-2025)*1000+MONTH(C32)*31+DAY(C32)+A32} -> 2734
A33: 1625 | B33: supplant | C33: 2026-03-15 | D33: 0 | E33: {=_xlfn.COUNTIFS(B3:B562,B33,D3:D562,1,A3:A562,A33)} -> 0 | F33: {=(YEAR(C33)-2025)*1000+MONTH(C33)*31+DAY(C33)+A33} -> 2733
A34: 1624 | B34: implant | C34: 2026-03-15 | D34: 1 | E34: {=_xlfn.COUNTIFS(B3:B562,B34,D3:D562,1,A3:A562,A34)} -> 1 | F34: {=(YEAR(C34)-2025)*1000+MONTH(C34)*31+DAY(C34)+A34} -> 2732
A35: 1623 | B35: plant | C35: 2026-03-15 | D35: 1 | E35: {=_xlfn.COUNTIFS(B3:B562,B35,D3:D562,1,A3:A562,A35)} -> 1 | F35: {=(YEAR(C35)-2025)*1000+MONTH(C35)*31+DAY(C35)+A35} -> 2731
A36: 1622 | B36: complain | C36: 2026-03-15 | D36: 1 | E36: {=_xlfn.COUNTIFS(B3:B562,B36,D3:D562,1,A3:A562,A36)} -> 1 | F36: {=(YEAR(C36)-2025)*1000+MONTH(C36)*31+DAY(C36)+A36} -> 2730
A37: 1621 | B37: explain | C37: 2026-03-15 | D37: 1 | E37: {=_xlfn.COUNTIFS(B3:B562,B37,D3:D562,1,A3:A562,A37)} -> 1 | F37: {=(YEAR(C37)-2025)*1000+MONTH(C37)*31+DAY(C37)+A37} -> 2729
A38: 1620 | B38: plain | C38: 2026-03-15 | D38: 1 | E38: {=_xlfn.COUNTIFS(B3:B562,B38,D3:D562,1,A3:A562,A38)} -> 1 | F38: {=(YEAR(C38)-2025)*1000+MONTH(C38)*31+DAY(C38)+A38} -> 2728
A39: 1619 | B39: planet | C39: 2026-03-15 | D39: 1 | E39: {=_xlfn.COUNTIFS(B3:B562,B39,D3:D562,1,A3:A562,A39)} -> 1 | F39: {=(YEAR(C39)-2025)*1000+MONTH(C39)*31+DAY(C39)+A39} -> 2727
A40: 1618 | B40: airplane | C40: 2026-03-15 | D40: 1 | E40: {=_xlfn.COUNTIFS(B3:B562,B40,D3:D562,1,A3:A562,A40)} -> 1 | F40: {=(YEAR(C40)-2025)*1000+MONTH(C40)*31+DAY(C40)+A40} -> 2726
A41: 1617 | B41: plan | C41: 2026-03-15 | D41: 1 | E41: {=_xlfn.COUNTIFS(B3:B562,B41,D3:D562,1,A3:A562,A41)} -> 1 | F41: {=(YEAR(C41)-2025)*1000+MONTH(C41)*31+DAY(C41)+A41} -> 2725
...

Sheet 총괄 - 틀린 것
A1: 틀린 것
A2: 틀린것 | B2: 영어단어 | C2: 외운것 | D2: No(전체 항목 세기)
A3: 1 | D3: 22

Sheet 총괄 - 전체
A1: 전체
A2: 외운 갯수 | B2: 남은 갯수
A3: {=COUNTIF('어휘 - 표 1 스냅샷'!J2:J2503,">=3")} -> 96 | B3: {=COUNTA('어휘 - 표 1 스냅샷'!A2:A2503)-A3} -> 2406

Sheet 총괄 - 3번 맞춘단어
A1: 3번 맞춘단어
B2: 날짜 | C2: 맞춘갯수(순서 체크) | D2: 회차
A3: 날짜: | C3: 합계:
A4: 46082 | C4: =SUM(C5:C23) -> 96
B5: 46094 | C5: {=COUNTIF('어휘 - 표 1 스냅샷'!L2:L2503,B5)} -> 0 | D5: {=COUNTIF('외운 것 - 엑셀다운로드 파일(붙여넣기)'!C3:C562,B5)/100} -> 1
B6: 46095 | C6: {=COUNTIF('어휘 - 표 1 스냅샷'!L2:L2503,B6)} -> 71 | D6: {=COUNTIF('외운 것 - 엑셀다운로드 파일(붙여넣기)'!C3:C562,B6)/100} -> 2
B7: 46096 | C7: {=COUNTIF('어휘 - 표 1 스냅샷'!L2:L2503,B7)} -> 4 | D7: {=COUNTIF('외운 것 - 엑셀다운로드 파일(붙여넣기)'!C3:C562,B7)/100} -> 0.6
B8: 46097 | C8: {=COUNTIF('어휘 - 표 1 스냅샷'!L2:L2503,B8)} -> 14 | D8: {=COUNTIF('외운 것 - 엑셀다운로드 파일(붙여넣기)'!C3:C562,B8)/100} -> 1
B9: 46098 | C9: {=COUNTIF('어휘 - 표 1 스냅샷'!L2:L2503,B9)} -> 7 | D9: {=COUNTIF('외운 것 - 엑셀다운로드 파일(붙여넣기)'!C3:C562,B9)/100} -> 1
B10: 46099 | C10: {=COUNTIF('어휘 - 표 1 스냅샷'!L2:L2503,B10)} -> 0 | D10: {=COUNTIF('외운 것 - 엑셀다운로드 파일(붙여넣기)'!C3:C562,B10)/100} -> 0
B11: 46100 | C11: {=COUNTIF('어휘 - 표 1 스냅샷'!L2:L2503,B11)} -> 0 | D11: {=COUNTIF('외운 것 - 엑셀다운로드 파일(붙여넣기)'!C3:C562,B11)/100} -> 0
B12: 46101 | C12: {=COUNTIF('어휘 - 표 1 스냅샷'!L2:L2503,B12)} -> 0 | D12: {=COUNTIF('외운 것 - 엑셀다운로드 파일(붙여넣기)'!C3:C562,B12)/100} -> 0
B13: 46102 | C13: {=COUNTIF('어휘 - 표 1 스냅샷'!L2:L2503,B13)} -> 0 | D13: {=COUNTIF('외운 것 - 엑셀다운로드 파일(붙여넣기)'!C3:C562,B13)/100} -> 0
B14: 46103 | C14: {=COUNTIF('어휘 - 표 1 스냅샷'!L2:L2503,B14)} -> 0 | D14: {=COUNTIF('외운 것 - 엑셀다운로드 파일(붙여넣기)'!C3:C562,B14)/100} -> 0
B15: 46104 | C15: {=COUNTIF('어휘 - 표 1 스냅샷'!L2:L2503,B15)} -> 0 | D15: {=COUNTIF('외운 것 - 엑셀다운로드 파일(붙여넣기)'!C3:C562,B15)/100} -> 0
B16: 46105 | C16: {=COUNTIF('어휘 - 표 1 스냅샷'!L2:L2503,B16)} -> 0 | D16: {=COUNTIF('외운 것 - 엑셀다운로드 파일(붙여넣기)'!C3:C562,B16)/100} -> 0
B17: 46106 | C17: {=COUNTIF('어휘 - 표 1 스냅샷'!L2:L2503,B17)} -> 0 | D17: {=COUNTIF('외운 것 - 엑셀다운로드 파일(붙여넣기)'!C3:C562,B17)/100} -> 0
B18: 46107 | C18: {=COUNTIF('어휘 - 표 1 스냅샷'!L2:L2503,B18)} -> 0 | D18: {=COUNTIF('외운 것 - 엑셀다운로드 파일(붙여넣기)'!C3:C562,B18)/100} -> 0
B19: 46108 | C19: {=COUNTIF('어휘 - 표 1 스냅샷'!L2:L2503,B19)} -> 0 | D19: {=COUNTIF('외운 것 - 엑셀다운로드 파일(붙여넣기)'!C3:C562,B19)/100} -> 0
B20: 46109 | C20: {=COUNTIF('어휘 - 표 1 스냅샷'!L2:L2503,B20)} -> 0 | D20: {=COUNTIF('외운 것 - 엑셀다운로드 파일(붙여넣기)'!C3:C562,B20)/100} -> 0
B21: 46110 | C21: {=COUNTIF('어휘 - 표 1 스냅샷'!L2:L2503,B21)} -> 0 | D21: {=COUNTIF('외운 것 - 엑셀다운로드 파일(붙여넣기)'!C3:C562,B21)/100} -> 0
B22: 46111 | C22: {=COUNTIF('어휘 - 표 1 스냅샷'!L2:L2503,B22)} -> 0 | D22: {=COUNTIF('외운 것 - 엑셀다운로드 파일(붙여넣기)'!C3:C562,B22)/100} -> 0
B23: 46112 | C23: {=COUNTIF('어휘 - 표 1 스냅샷'!L2:L2503,B23)} -> 0 | D23: {=COUNTIF('외운 것 - 엑셀다운로드 파일(붙여넣기)'!C3:C562,B23)/100} -> 0
A24: 46113 | C24: =SUM(C25:C54) -> 0
B25: 46113 | C25: {=COUNTIF('어휘 - 표 1 스냅샷'!L2:L2503,B25)} -> 0 | D25: {=COUNTIF('외운 것 - 엑셀다운로드 파일(붙여넣기)'!C3:C562,B25)/100} -> 0
B26: 46114 | C26: {=COUNTIF('어휘 - 표 1 스냅샷'!L2:L2503,B26)} -> 0 | D26: {=COUNTIF('외운 것 - 엑셀다운로드 파일(붙여넣기)'!C3:C562,B26)/100} -> 0
B27: 46115 | C27: {=COUNTIF('어휘 - 표 1 스냅샷'!L2:L2503,B27)} -> 0 | D27: {=COUNTIF('외운 것 - 엑셀다운로드 파일(붙여넣기)'!C3:C562,B27)/100} -> 0
B28: 46116 | C28: {=COUNTIF('어휘 - 표 1 스냅샷'!L2:L2503,B28)} -> 0 | D28: {=COUNTIF('외운 것 - 엑셀다운로드 파일(붙여넣기)'!C3:C562,B28)/100} -> 0
B29: 46117 | C29: {=COUNTIF('어휘 - 표 1 스냅샷'!L2:L2503,B29)} -> 0 | D29: {=COUNTIF('외운 것 - 엑셀다운로드 파일(붙여넣기)'!C3:C562,B29)/100} -> 0
B30: 46118 | C30: {=COUNTIF('어휘 - 표 1 스냅샷'!L2:L2503,B30)} -> 0 | D30: {=COUNTIF('외운 것 - 엑셀다운로드 파일(붙여넣기)'!C3:C562,B30)/100} -> 0
B31: 46119 | C31: {=COUNTIF('어휘 - 표 1 스냅샷'!L2:L2503,B31)} -> 0 | D31: {=COUNTIF('외운 것 - 엑셀다운로드 파일(붙여넣기)'!C3:C562,B31)/100} -> 0
B32: 46120 | C32: {=COUNTIF('어휘 - 표 1 스냅샷'!L2:L2503,B32)} -> 0 | D32: {=COUNTIF('외운 것 - 엑셀다운로드 파일(붙여넣기)'!C3:C562,B32)/100} -> 0
B33: 46121 | C33: {=COUNTIF('어휘 - 표 1 스냅샷'!L2:L2503,B33)} -> 0 | D33: {=COUNTIF('외운 것 - 엑셀다운로드 파일(붙여넣기)'!C3:C562,B33)/100} -> 0
B34: 46122 | C34: {=COUNTIF('어휘 - 표 1 스냅샷'!L2:L2503,B34)} -> 0 | D34: {=COUNTIF('외운 것 - 엑셀다운로드 파일(붙여넣기)'!C3:C562,B34)/100} -> 0
B35: 46123 | C35: {=COUNTIF('어휘 - 표 1 스냅샷'!L2:L2503,B35)} -> 0 | D35: {=COUNTIF('외운 것 - 엑셀다운로드 파일(붙여넣기)'!C3:C562,B35)/100} -> 0
B36: 46124 | C36: {=COUNTIF('어휘 - 표 1 스냅샷'!L2:L2503,B36)} -> 0 | D36: {=COUNTIF('외운 것 - 엑셀다운로드 파일(붙여넣기)'!C3:C562,B36)/100} -> 0
B37: 46125 | C37: {=COUNTIF('어휘 - 표 1 스냅샷'!L2:L2503,B37)} -> 0 | D37: {=COUNTIF('외운 것 - 엑셀다운로드 파일(붙여넣기)'!C3:C562,B37)/100} -> 0
B38: 46126 | C38: {=COUNTIF('어휘 - 표 1 스냅샷'!L2:L2503,B38)} -> 0 | D38: {=COUNTIF('외운 것 - 엑셀다운로드 파일(붙여넣기)'!C3:C562,B38)/100} -> 0
B39: 46127 | C39: {=COUNTIF('어휘 - 표 1 스냅샷'!L2:L2503,B39)} -> 0 | D39: {=COUNTIF('외운 것 - 엑셀다운로드 파일(붙여넣기)'!C3:C562,B39)/100} -> 0
B40: 46128 | C40: {=COUNTIF('어휘 - 표 1 스냅샷'!L2:L2503,B40)} -> 0 | D40: {=COUNTIF('외운 것 - 엑셀다운로드 파일(붙여넣기)'!C3:C562,B40)/100} -> 0
...
